Workbook

Sheet Start here
B4: Change Authority Review
B5: Your agent’s access says what it can do. Decide who gives it the authority to act.
B7: WHAT TO BRING | C7: One agent and the artifact or system it changes; a list of every action it can take (edit, save a version, restore, delete, publish, send, notify, change permissions, call an external API); and a test environment where you can try undoing each action.
B9: WHAT TO DO | C9: List every action, try to undo each one and record what remains, give each action an authority level (Agent acts, Preview and consent or Not allowed), fill in what each level needs, and score the ten checks.
B11: WHAT YOU LEAVE WITH | C11: An authority map for that agent (each action, whether it can really be undone, who authorises it and what the preview must show), a list of actions whose authority isn’t ready, and a decision: Ready, Fix first or Hold.
B13: THE THREE AUTHORITY LEVELS
B14: Authority | C14: Use it when | D14: What it needs before the agent may act
B15: Agent acts | C15: The action can be fully undone, and nobody but the user sees the result before it can be undone | D15: An undo path that has been tested, not assumed
B16: Preview and consent | C16: The action can’t be fully undone, or other people or systems see the result | D16: A preview showing the full change and what can’t be undone; a named person who consents to each change; the agent acting as that person; a safe outcome if they say no
B17: Not allowed | C17: The agent doesn’t need this action | D17: The access removed, not just unused
B19: CAN IT BE UNDONE?
B20: Answer | C20: Meaning | D20: Example
B21: Yes | C21: An undo leaves nothing anyone could act on | D21: Discarding a draft in the editor preview
B22: Partly | C22: The content can be restored, but a trace remains: a history entry, a notification, a copy, a link someone saved | D22: Saving a new version; restoring an earlier version
B23: No | C23: It can’t be undone | D23: Publishing; sending a message; notifying people
B25: HOW TO USE IT | C25: Work left to right through tabs 1–3. The Worked Example tab shows a completed version.
B26: 1 · Action Inventory | C26: What can the agent do, and can each action really be undone?
B27: 2 · Authority Requirements | C27: Does each authority level have what it needs?
B28: 3 · Checklist | C28: Is the agent’s authority ready for real users?
B30: CELL LEGEND | C30: Shaded cells are yours to fill. Everything else calculates.
C31: Yours to fill | D31: Shaded, with a thin border.
C32: Calculates for you | D32: No fill, and locked.
C33: Does not apply | D33: On Tab 2, a column that is not for this row’s authority.
B35: © The Living Craft · thelivingcraft.ai · Content CC BY 4.0
B36: Built by Sunil Mathew, co-authored with Claude
B38: THE LIVING CRAFT COHORT | C38: Build a working agentic system and develop the reasoning behind it. Explore The Living Craft’s October 2026 cohort: 30 live hours with Sunil Mathew, plus independent work.
C39: Apply at https://learning.thelivingcraft.ai/#apply

Sheet 1 · Action Inventory
A1: 1 · Action Inventory | Z1: Yes
A2: What can the agent do, and can each action really be undone? | Z2: Partly
A3: Mark each action from a real undo attempt. Saving a version, restoring a version and renaming often feel reversible. Check what the history, notifications and other people’s screens show afterwards. | Z3: No
A5: # | B5: Action | C5: What it changes | D5: Can it be undone? | E5: Who sees the result before it can be undone? | F5: Undo tested? | G5: Suggested authority | H5: Authority chosen | I5: Final authority | J5: Differs from suggestion? | K5: Reason for the difference | Z5: Nobody
A6: 1 | G6: =IF(OR(B6="",D6="",E6=""),"",IF(AND(D6="Yes",OR(E6="Nobody",E6="The user only")),"Agent acts","Preview and consent")) | I6: =IF(H6<>"",H6,G6) | J6: =IF(AND(H6<>"",H6<>G6),"Yes","") | Z6: The user only
A7: 2 | G7: =IF(OR(B7="",D7="",E7=""),"",IF(AND(D7="Yes",OR(E7="Nobody",E7="The user only")),"Agent acts","Preview and consent")) | I7: =IF(H7<>"",H7,G7) | J7: =IF(AND(H7<>"",H7<>G7),"Yes","") | Z7: Other people
A8: 3 | G8: =IF(OR(B8="",D8="",E8=""),"",IF(AND(D8="Yes",OR(E8="Nobody",E8="The user only")),"Agent acts","Preview and consent")) | I8: =IF(H8<>"",H8,G8) | J8: =IF(AND(H8<>"",H8<>G8),"Yes","") | Z8: Another system
A9: 4 | G9: =IF(OR(B9="",D9="",E9=""),"",IF(AND(D9="Yes",OR(E9="Nobody",E9="The user only")),"Agent acts","Preview and consent")) | I9: =IF(H9<>"",H9,G9) | J9: =IF(AND(H9<>"",H9<>G9),"Yes","")
A10: 5 | G10: =IF(OR(B10="",D10="",E10=""),"",IF(AND(D10="Yes",OR(E10="Nobody",E10="The user only")),"Agent acts","Preview and consent")) | I10: =IF(H10<>"",H10,G10) | J10: =IF(AND(H10<>"",H10<>G10),"Yes","") | Z10: Yes
A11: 6 | G11: =IF(OR(B11="",D11="",E11=""),"",IF(AND(D11="Yes",OR(E11="Nobody",E11="The user only")),"Agent acts","Preview and consent")) | I11: =IF(H11<>"",H11,G11) | J11: =IF(AND(H11<>"",H11<>G11),"Yes","") | Z11: No
A12: 7 | G12: =IF(OR(B12="",D12="",E12=""),"",IF(AND(D12="Yes",OR(E12="Nobody",E12="The user only")),"Agent acts","Preview and consent")) | I12: =IF(H12<>"",H12,G12) | J12: =IF(AND(H12<>"",H12<>G12),"Yes","")
A13: 8 | G13: =IF(OR(B13="",D13="",E13=""),"",IF(AND(D13="Yes",OR(E13="Nobody",E13="The user only")),"Agent acts","Preview and consent")) | I13: =IF(H13<>"",H13,G13) | J13: =IF(AND(H13<>"",H13<>G13),"Yes","") | Z13: Agent acts
A14: 9 | G14: =IF(OR(B14="",D14="",E14=""),"",IF(AND(D14="Yes",OR(E14="Nobody",E14="The user only")),"Agent acts","Preview and consent")) | I14: =IF(H14<>"",H14,G14) | J14: =IF(AND(H14<>"",H14<>G14),"Yes","") | Z14: Preview and consent
A15: 10 | G15: =IF(OR(B15="",D15="",E15=""),"",IF(AND(D15="Yes",OR(E15="Nobody",E15="The user only")),"Agent acts","Preview and consent")) | I15: =IF(H15<>"",H15,G15) | J15: =IF(AND(H15<>"",H15<>G15),"Yes","") | Z15: Not allowed
A16: 11 | G16: =IF(OR(B16="",D16="",E16=""),"",IF(AND(D16="Yes",OR(E16="Nobody",E16="The user only")),"Agent acts","Preview and consent")) | I16: =IF(H16<>"",H16,G16) | J16: =IF(AND(H16<>"",H16<>G16),"Yes","")
A17: 12 | G17: =IF(OR(B17="",D17="",E17=""),"",IF(AND(D17="Yes",OR(E17="Nobody",E17="The user only")),"Agent acts","Preview and consent")) | I17: =IF(H17<>"",H17,G17) | J17: =IF(AND(H17<>"",H17<>G17),"Yes","")
A18: 13 | G18: =IF(OR(B18="",D18="",E18=""),"",IF(AND(D18="Yes",OR(E18="Nobody",E18="The user only")),"Agent acts","Preview and consent")) | I18: =IF(H18<>"",H18,G18) | J18: =IF(AND(H18<>"",H18<>G18),"Yes","")
A19: 14 | G19: =IF(OR(B19="",D19="",E19=""),"",IF(AND(D19="Yes",OR(E19="Nobody",E19="The user only")),"Agent acts","Preview and consent")) | I19: =IF(H19<>"",H19,G19) | J19: =IF(AND(H19<>"",H19<>G19),"Yes","")
A20: 15 | G20: =IF(OR(B20="",D20="",E20=""),"",IF(AND(D20="Yes",OR(E20="Nobody",E20="The user only")),"Agent acts","Preview and consent")) | I20: =IF(H20<>"",H20,G20) | J20: =IF(AND(H20<>"",H20<>G20),"Yes","")
A21: 16 | G21: =IF(OR(B21="",D21="",E21=""),"",IF(AND(D21="Yes",OR(E21="Nobody",E21="The user only")),"Agent acts","Preview and consent")) | I21: =IF(H21<>"",H21,G21) | J21: =IF(AND(H21<>"",H21<>G21),"Yes","")
A22: 17 | G22: =IF(OR(B22="",D22="",E22=""),"",IF(AND(D22="Yes",OR(E22="Nobody",E22="The user only")),"Agent acts","Preview and consent")) | I22: =IF(H22<>"",H22,G22) | J22: =IF(AND(H22<>"",H22<>G22),"Yes","")
A23: 18 | G23: =IF(OR(B23="",D23="",E23=""),"",IF(AND(D23="Yes",OR(E23="Nobody",E23="The user only")),"Agent acts","Preview and consent")) | I23: =IF(H23<>"",H23,G23) | J23: =IF(AND(H23<>"",H23<>G23),"Yes","")
A24: 19 | G24: =IF(OR(B24="",D24="",E24=""),"",IF(AND(D24="Yes",OR(E24="Nobody",E24="The user only")),"Agent acts","Preview and consent")) | I24: =IF(H24<>"",H24,G24) | J24: =IF(AND(H24<>"",H24<>G24),"Yes","")
A25: 20 | G25: =IF(OR(B25="",D25="",E25=""),"",IF(AND(D25="Yes",OR(E25="Nobody",E25="The user only")),"Agent acts","Preview and consent")) | I25: =IF(H25<>"",H25,G25) | J25: =IF(AND(H25<>"",H25<>G25),"Yes","")
A27: Summary
A28: Actions listed | C28: =COUNTA(B6:B25)
A30: ACTIONS BY AUTHORITY | C30: Final | D30: Suggested
B31: Agent acts | C31: =COUNTIF(I6:I25,"Agent acts") | D31: =COUNTIF(G6:G25,"Agent acts")
B32: Preview and consent | C32: =COUNTIF(I6:I25,"Preview and consent") | D32: =COUNTIF(G6:G25,"Preview and consent")
B33: Not allowed | C33: =COUNTIF(I6:I25,"Not allowed") | D33: =COUNTIF(G6:G25,"Not allowed")
A35: Actions with no authority | C35: =SUMPRODUCT((B6:B25<>"")*(I6:I25="")) | D35: Actions with a name and no authority. Fill in D and E, or choose an authority.
A36: Undo not tested | C36: =SUMPRODUCT((B6:B25<>"")*(F6:F25<>"Yes")) | D36: Actions where nobody has actually tried the undo.
A37: Overrides | C37: =COUNTIF(J6:J25,"Yes") | D37: Actions where the authority chosen differs from the suggestion.
A38: Overrides with no reason | C38: =SUMPRODUCT((J6:J25="Yes")*(K6:K25="")) | D38: Write the reason in column K.
A39: Actions that need consent but the agent takes alone | C39: =COUNTIFS(G6:G25,"Preview and consent",I6:I25,"Agent acts") | D39: Suggested Preview and consent, chosen Agent acts: an override that removed consent.

Sheet 2 · Authority Requirements
A1: 2 · Authority Requirements | Z1: Yes
A2: Does each authority level have what it needs? | Z2: No
A3: Rows mirror the Action Inventory. Fill in only the columns for the row’s final authority; the others are greyed out. Each row names the first thing missing.
Z4: Yes
E5: Agent acts | F5: Preview and consent | L5: Not allowed | Z5: Partial
A6: # | B6: Action | C6: Final authority | D6: Undo tested? | E6: Undo path | F6: Preview shows the full change? | G6: Preview says what can’t be undone? | H6: Who consents | I6: Consent is given per change (not a standing “always allow”)? | J6: Agent acts as that person, and the log records who approved? | K6: If consent is refused, the agent… | L6: Access removed? | M6: Authority ready? | N6: Why not ready | Z6: No
A7: 1 | B7: =IF('1 · Action Inventory'!B6="","",'1 · Action Inventory'!B6) | C7: =IF('1 · Action Inventory'!I6="","",'1 · Action Inventory'!I6) | D7: =IF('1 · Action Inventory'!F6="","",'1 · Action Inventory'!F6) | M7: =IF(C7="","",IF(N7="","Ready","Not ready")) | N7: =IF(C7="","",IF(C7="Agent acts",IF(E7="","No undo path",IF(D7<>"Yes","Undo not tested","")),IF(C7="Preview and consent",IF(F7<>"Yes","Preview doesn’t show the full change",IF(G7<>"Yes","Preview doesn’t say what can’t be undone",IF(H7="","No named person gives consent",IF(I7<>"Yes","Consent is a standing default, not per change",IF(J7<>"Yes","Agent doesn’t act as the consenting person",IF(AND(K7<>"Changes nothing",K7<>"Revises and asks again"),"No safe outcome when consent is refused","")))))),IF(C7="Not allowed",IF(L7<>"Yes","Access not removed",""),""))))
A8: 2 | B8: =IF('1 · Action Inventory'!B7="","",'1 · Action Inventory'!B7) | C8: =IF('1 · Action Inventory'!I7="","",'1 · Action Inventory'!I7) | D8: =IF('1 · Action Inventory'!F7="","",'1 · Action Inventory'!F7) | M8: =IF(C8="","",IF(N8="","Ready","Not ready")) | N8: =IF(C8="","",IF(C8="Agent acts",IF(E8="","No undo path",IF(D8<>"Yes","Undo not tested","")),IF(C8="Preview and consent",IF(F8<>"Yes","Preview doesn’t show the full change",IF(G8<>"Yes","Preview doesn’t say what can’t be undone",IF(H8="","No named person gives consent",IF(I8<>"Yes","Consent is a standing default, not per change",IF(J8<>"Yes","Agent doesn’t act as the consenting person",IF(AND(K8<>"Changes nothing",K8<>"Revises and asks again"),"No safe outcome when consent is refused","")))))),IF(C8="Not allowed",IF(L8<>"Yes","Access not removed",""),"")))) | Z8: Changes nothing
A9: 3 | B9: =IF('1 · Action Inventory'!B8="","",'1 · Action Inventory'!B8) | C9: =IF('1 · Action Inventory'!I8="","",'1 · Action Inventory'!I8) | D9: =IF('1 · Action Inventory'!F8="","",'1 · Action Inventory'!F8) | M9: =IF(C9="","",IF(N9="","Ready","Not ready")) | N9: =IF(C9="","",IF(C9="Agent acts",IF(E9="","No undo path",IF(D9<>"Yes","Undo not tested","")),IF(C9="Preview and consent",IF(F9<>"Yes","Preview doesn’t show the full change",IF(G9<>"Yes","Preview doesn’t say what can’t be undone",IF(H9="","No named person gives consent",IF(I9<>"Yes","Consent is a standing default, not per change",IF(J9<>"Yes","Agent doesn’t act as the consenting person",IF(AND(K9<>"Changes nothing",K9<>"Revises and asks again"),"No safe outcome when consent is refused","")))))),IF(C9="Not allowed",IF(L9<>"Yes","Access not removed",""),"")))) | Z9: Revises and asks again
A10: 4 | B10: =IF('1 · Action Inventory'!B9="","",'1 · Action Inventory'!B9) | C10: =IF('1 · Action Inventory'!I9="","",'1 · Action Inventory'!I9) | D10: =IF('1 · Action Inventory'!F9="","",'1 · Action Inventory'!F9) | M10: =IF(C10="","",IF(N10="","Ready","Not ready")) | N10: =IF(C10="","",IF(C10="Agent acts",IF(E10="","No undo path",IF(D10<>"Yes","Undo not tested","")),IF(C10="Preview and consent",IF(F10<>"Yes","Preview doesn’t show the full change",IF(G10<>"Yes","Preview doesn’t say what can’t be undone",IF(H10="","No named person gives consent",IF(I10<>"Yes","Consent is a standing default, not per change",IF(J10<>"Yes","Agent doesn’t act as the consenting person",IF(AND(K10<>"Changes nothing",K10<>"Revises and asks again"),"No safe outcome when consent is refused","")))))),IF(C10="Not allowed",IF(L10<>"Yes","Access not removed",""),"")))) | Z10: Proceeds anyway
A11: 5 | B11: =IF('1 · Action Inventory'!B10="","",'1 · Action Inventory'!B10) | C11: =IF('1 · Action Inventory'!I10="","",'1 · Action Inventory'!I10) | D11: =IF('1 · Action Inventory'!F10="","",'1 · Action Inventory'!F10) | M11: =IF(C11="","",IF(N11="","Ready","Not ready")) | N11: =IF(C11="","",IF(C11="Agent acts",IF(E11="","No undo path",IF(D11<>"Yes","Undo not tested","")),IF(C11="Preview and consent",IF(F11<>"Yes","Preview doesn’t show the full change",IF(G11<>"Yes","Preview doesn’t say what can’t be undone",IF(H11="","No named person gives consent",IF(I11<>"Yes","Consent is a standing default, not per change",IF(J11<>"Yes","Agent doesn’t act as the consenting person",IF(AND(K11<>"Changes nothing",K11<>"Revises and asks again"),"No safe outcome when consent is refused","")))))),IF(C11="Not allowed",IF(L11<>"Yes","Access not removed",""),"")))) | Z11: Not decided
A12: 6 | B12: =IF('1 · Action Inventory'!B11="","",'1 · Action Inventory'!B11) | C12: =IF('1 · Action Inventory'!I11="","",'1 · Action Inventory'!I11) | D12: =IF('1 · Action Inventory'!F11="","",'1 · Action Inventory'!F11) | M12: =IF(C12="","",IF(N12="","Ready","Not ready")) | N12: =IF(C12="","",IF(C12="Agent acts",IF(E12="","No undo path",IF(D12<>"Yes","Undo not tested","")),IF(C12="Preview and consent",IF(F12<>"Yes","Preview doesn’t show the full change",IF(G12<>"Yes","Preview doesn’t say what can’t be undone",IF(H12="","No named person gives consent",IF(I12<>"Yes","Consent is a standing default, not per change",IF(J12<>"Yes","Agent doesn’t act as the consenting person",IF(AND(K12<>"Changes nothing",K12<>"Revises and asks again"),"No safe outcome when consent is refused","")))))),IF(C12="Not allowed",IF(L12<>"Yes","Access not removed",""),""))))
A13: 7 | B13: =IF('1 · Action Inventory'!B12="","",'1 · Action Inventory'!B12) | C13: =IF('1 · Action Inventory'!I12="","",'1 · Action Inventory'!I12) | D13: =IF('1 · Action Inventory'!F12="","",'1 · Action Inventory'!F12) | M13: =IF(C13="","",IF(N13="","Ready","Not ready")) | N13: =IF(C13="","",IF(C13="Agent acts",IF(E13="","No undo path",IF(D13<>"Yes","Undo not tested","")),IF(C13="Preview and consent",IF(F13<>"Yes","Preview doesn’t show the full change",IF(G13<>"Yes","Preview doesn’t say what can’t be undone",IF(H13="","No named person gives consent",IF(I13<>"Yes","Consent is a standing default, not per change",IF(J13<>"Yes","Agent doesn’t act as the consenting person",IF(AND(K13<>"Changes nothing",K13<>"Revises and asks again"),"No safe outcome when consent is refused","")))))),IF(C13="Not allowed",IF(L13<>"Yes","Access not removed",""),""))))
A14: 8 | B14: =IF('1 · Action Inventory'!B13="","",'1 · Action Inventory'!B13) | C14: =IF('1 · Action Inventory'!I13="","",'1 · Action Inventory'!I13) | D14: =IF('1 · Action Inventory'!F13="","",'1 · Action Inventory'!F13) | M14: =IF(C14="","",IF(N14="","Ready","Not ready")) | N14: =IF(C14="","",IF(C14="Agent acts",IF(E14="","No undo path",IF(D14<>"Yes","Undo not tested","")),IF(C14="Preview and consent",IF(F14<>"Yes","Preview doesn’t show the full change",IF(G14<>"Yes","Preview doesn’t say what can’t be undone",IF(H14="","No named person gives consent",IF(I14<>"Yes","Consent is a standing default, not per change",IF(J14<>"Yes","Agent doesn’t act as the consenting person",IF(AND(K14<>"Changes nothing",K14<>"Revises and asks again"),"No safe outcome when consent is refused","")))))),IF(C14="Not allowed",IF(L14<>"Yes","Access not removed",""),""))))
A15: 9 | B15: =IF('1 · Action Inventory'!B14="","",'1 · Action Inventory'!B14) | C15: =IF('1 · Action Inventory'!I14="","",'1 · Action Inventory'!I14) | D15: =IF('1 · Action Inventory'!F14="","",'1 · Action Inventory'!F14) | M15: =IF(C15="","",IF(N15="","Ready","Not ready")) | N15: =IF(C15="","",IF(C15="Agent acts",IF(E15="","No undo path",IF(D15<>"Yes","Undo not tested","")),IF(C15="Preview and consent",IF(F15<>"Yes","Preview doesn’t show the full change",IF(G15<>"Yes","Preview doesn’t say what can’t be undone",IF(H15="","No named person gives consent",IF(I15<>"Yes","Consent is a standing default, not per change",IF(J15<>"Yes","Agent doesn’t act as the consenting person",IF(AND(K15<>"Changes nothing",K15<>"Revises and asks again"),"No safe outcome when consent is refused","")))))),IF(C15="Not allowed",IF(L15<>"Yes","Access not removed",""),""))))
A16: 10 | B16: =IF('1 · Action Inventory'!B15="","",'1 · Action Inventory'!B15) | C16: =IF('1 · Action Inventory'!I15="","",'1 · Action Inventory'!I15) | D16: =IF('1 · Action Inventory'!F15="","",'1 · Action Inventory'!F15) | M16: =IF(C16="","",IF(N16="","Ready","Not ready")) | N16: =IF(C16="","",IF(C16="Agent acts",IF(E16="","No undo path",IF(D16<>"Yes","Undo not tested","")),IF(C16="Preview and consent",IF(F16<>"Yes","Preview doesn’t show the full change",IF(G16<>"Yes","Preview doesn’t say what can’t be undone",IF(H16="","No named person gives consent",IF(I16<>"Yes","Consent is a standing default, not per change",IF(J16<>"Yes","Agent doesn’t act as the consenting person",IF(AND(K16<>"Changes nothing",K16<>"Revises and asks again"),"No safe outcome when consent is refused","")))))),IF(C16="Not allowed",IF(L16<>"Yes","Access not removed",""),""))))
A17: 11 | B17: =IF('1 · Action Inventory'!B16="","",'1 · Action Inventory'!B16) | C17: =IF('1 · Action Inventory'!I16="","",'1 · Action Inventory'!I16) | D17: =IF('1 · Action Inventory'!F16="","",'1 · Action Inventory'!F16) | M17: =IF(C17="","",IF(N17="","Ready","Not ready")) | N17: =IF(C17="","",IF(C17="Agent acts",IF(E17="","No undo path",IF(D17<>"Yes","Undo not tested","")),IF(C17="Preview and consent",IF(F17<>"Yes","Preview doesn’t show the full change",IF(G17<>"Yes","Preview doesn’t say what can’t be undone",IF(H17="","No named person gives consent",IF(I17<>"Yes","Consent is a standing default, not per change",IF(J17<>"Yes","Agent doesn’t act as the consenting person",IF(AND(K17<>"Changes nothing",K17<>"Revises and asks again"),"No safe outcome when consent is refused","")))))),IF(C17="Not allowed",IF(L17<>"Yes","Access not removed",""),""))))
A18: 12 | B18: =IF('1 · Action Inventory'!B17="","",'1 · Action Inventory'!B17) | C18: =IF('1 · Action Inventory'!I17="","",'1 · Action Inventory'!I17) | D18: =IF('1 · Action Inventory'!F17="","",'1 · Action Inventory'!F17) | M18: =IF(C18="","",IF(N18="","Ready","Not ready")) | N18: =IF(C18="","",IF(C18="Agent acts",IF(E18="","No undo path",IF(D18<>"Yes","Undo not tested","")),IF(C18="Preview and consent",IF(F18<>"Yes","Preview doesn’t show the full change",IF(G18<>"Yes","Preview doesn’t say what can’t be undone",IF(H18="","No named person gives consent",IF(I18<>"Yes","Consent is a standing default, not per change",IF(J18<>"Yes","Agent doesn’t act as the consenting person",IF(AND(K18<>"Changes nothing",K18<>"Revises and asks again"),"No safe outcome when consent is refused","")))))),IF(C18="Not allowed",IF(L18<>"Yes","Access not removed",""),""))))
A19: 13 | B19: =IF('1 · Action Inventory'!B18="","",'1 · Action Inventory'!B18) | C19: =IF('1 · Action Inventory'!I18="","",'1 · Action Inventory'!I18) | D19: =IF('1 · Action Inventory'!F18="","",'1 · Action Inventory'!F18) | M19: =IF(C19="","",IF(N19="","Ready","Not ready")) | N19: =IF(C19="","",IF(C19="Agent acts",IF(E19="","No undo path",IF(D19<>"Yes","Undo not tested","")),IF(C19="Preview and consent",IF(F19<>"Yes","Preview doesn’t show the full change",IF(G19<>"Yes","Preview doesn’t say what can’t be undone",IF(H19="","No named person gives consent",IF(I19<>"Yes","Consent is a standing default, not per change",IF(J19<>"Yes","Agent doesn’t act as the consenting person",IF(AND(K19<>"Changes nothing",K19<>"Revises and asks again"),"No safe outcome when consent is refused","")))))),IF(C19="Not allowed",IF(L19<>"Yes","Access not removed",""),""))))
A20: 14 | B20: =IF('1 · Action Inventory'!B19="","",'1 · Action Inventory'!B19) | C20: =IF('1 · Action Inventory'!I19="","",'1 · Action Inventory'!I19) | D20: =IF('1 · Action Inventory'!F19="","",'1 · Action Inventory'!F19) | M20: =IF(C20="","",IF(N20="","Ready","Not ready")) | N20: =IF(C20="","",IF(C20="Agent acts",IF(E20="","No undo path",IF(D20<>"Yes","Undo not tested","")),IF(C20="Preview and consent",IF(F20<>"Yes","Preview doesn’t show the full change",IF(G20<>"Yes","Preview doesn’t say what can’t be undone",IF(H20="","No named person gives consent",IF(I20<>"Yes","Consent is a standing default, not per change",IF(J20<>"Yes","Agent doesn’t act as the consenting person",IF(AND(K20<>"Changes nothing",K20<>"Revises and asks again"),"No safe outcome when consent is refused","")))))),IF(C20="Not allowed",IF(L20<>"Yes","Access not removed",""),""))))
A21: 15 | B21: =IF('1 · Action Inventory'!B20="","",'1 · Action Inventory'!B20) | C21: =IF('1 · Action Inventory'!I20="","",'1 · Action Inventory'!I20) | D21: =IF('1 · Action Inventory'!F20="","",'1 · Action Inventory'!F20) | M21: =IF(C21="","",IF(N21="","Ready","Not ready")) | N21: =IF(C21="","",IF(C21="Agent acts",IF(E21="","No undo path",IF(D21<>"Yes","Undo not tested","")),IF(C21="Preview and consent",IF(F21<>"Yes","Preview doesn’t show the full change",IF(G21<>"Yes","Preview doesn’t say what can’t be undone",IF(H21="","No named person gives consent",IF(I21<>"Yes","Consent is a standing default, not per change",IF(J21<>"Yes","Agent doesn’t act as the consenting person",IF(AND(K21<>"Changes nothing",K21<>"Revises and asks again"),"No safe outcome when consent is refused","")))))),IF(C21="Not allowed",IF(L21<>"Yes","Access not removed",""),""))))
A22: 16 | B22: =IF('1 · Action Inventory'!B21="","",'1 · Action Inventory'!B21) | C22: =IF('1 · Action Inventory'!I21="","",'1 · Action Inventory'!I21) | D22: =IF('1 · Action Inventory'!F21="","",'1 · Action Inventory'!F21) | M22: =IF(C22="","",IF(N22="","Ready","Not ready")) | N22: =IF(C22="","",IF(C22="Agent acts",IF(E22="","No undo path",IF(D22<>"Yes","Undo not tested","")),IF(C22="Preview and consent",IF(F22<>"Yes","Preview doesn’t show the full change",IF(G22<>"Yes","Preview doesn’t say what can’t be undone",IF(H22="","No named person gives consent",IF(I22<>"Yes","Consent is a standing default, not per change",IF(J22<>"Yes","Agent doesn’t act as the consenting person",IF(AND(K22<>"Changes nothing",K22<>"Revises and asks again"),"No safe outcome when consent is refused","")))))),IF(C22="Not allowed",IF(L22<>"Yes","Access not removed",""),""))))
A23: 17 | B23: =IF('1 · Action Inventory'!B22="","",'1 · Action Inventory'!B22) | C23: =IF('1 · Action Inventory'!I22="","",'1 · Action Inventory'!I22) | D23: =IF('1 · Action Inventory'!F22="","",'1 · Action Inventory'!F22) | M23: =IF(C23="","",IF(N23="","Ready","Not ready")) | N23: =IF(C23="","",IF(C23="Agent acts",IF(E23="","No undo path",IF(D23<>"Yes","Undo not tested","")),IF(C23="Preview and consent",IF(F23<>"Yes","Preview doesn’t show the full change",IF(G23<>"Yes","Preview doesn’t say what can’t be undone",IF(H23="","No named person gives consent",IF(I23<>"Yes","Consent is a standing default, not per change",IF(J23<>"Yes","Agent doesn’t act as the consenting person",IF(AND(K23<>"Changes nothing",K23<>"Revises and asks again"),"No safe outcome when consent is refused","")))))),IF(C23="Not allowed",IF(L23<>"Yes","Access not removed",""),""))))
... A26: 20 | B26: =IF('1 · Action Inventory'!B25="","",'1 · Action Inventory'!B25) | C26: =IF('1 · Action Inventory'!I25="","",'1 · Action Inventory'!I25) | D26: =IF('1 · Action Inventory'!F25="","",'1 · Action Inventory'!F25) | M26: =IF(C26="","",IF(N26="","Ready","Not ready")) | N26: =IF(C26="","",IF(C26="Agent acts",IF(E26="","No undo path",IF(D26<>"Yes","Undo not tested","")),IF(C26="Preview and consent",IF(F26<>"Yes","Preview doesn’t show the full change",IF(G26<>"Yes","Preview doesn’t say what can’t be undone",IF(H26="","No named person gives consent",IF(I26<>"Yes","Consent is a standing default, not per change",IF(J26<>"Yes","Agent doesn’t act as the consenting person",IF(AND(K26<>"Changes nothing",K26<>"Revises and asks again"),"No safe outcome when consent is refused","")))))),IF(C26="Not allowed",IF(L26<>"Yes","Access not removed",""),""))))
A28: Summary
A29: BY AUTHORITY | C29: Actions | D29: Ready
B30: Agent acts | C30: =COUNTIF(C7:C26,"Agent acts") | D30: =COUNTIFS(C7:C26,"Agent acts",M7:M26,"Ready")
B31: Preview and consent | C31: =COUNTIF(C7:C26,"Preview and consent") | D31: =COUNTIFS(C7:C26,"Preview and consent",M7:M26,"Ready")
B32: Not allowed | C32: =COUNTIF(C7:C26,"Not allowed") | D32: =COUNTIFS(C7:C26,"Not allowed",M7:M26,"Ready")
A34: Authority not ready | C34: =COUNTIF(M7:M26,"Not ready") | D34: Column N names the first thing missing on each.
A35: Previews that hide part of the change | C35: =SUMPRODUCT((C7:C26="Preview and consent")*(((F7:F26<>"Yes")+(G7:G26<>"Yes"))>0)) | D35: The preview does not show the full change, or does not say what can’t be undone.
A36: Consent that isn’t per change or has no named person | C36: =SUMPRODUCT((C7:C26="Preview and consent")*(((I7:I26<>"Yes")+(H7:H26=""))>0))
A37: Agent not acting as the consenting person | C37: =SUMPRODUCT((C7:C26="Preview and consent")*(J7:J26<>"Yes"))
A38: No safe outcome on refusal | C38: =SUMPRODUCT((C7:C26="Preview and consent")*(K7:K26<>"Changes nothing")*(K7:K26<>"Revises and asks again")) | D38: Proceeds anyway, Not decided, or left blank.
A39: Not allowed, access still present | C39: =SUMPRODUCT((C7:C26="Not allowed")*(L7:L26<>"Yes"))

Sheet 3 · Checklist
A1: 3 · Checklist | Z1: Yes
A2: Is the agent’s authority ready for real users? | Z2: Partial
A3: Answer each check from evidence, not from memory. The four marked ★ are critical: a No on any one of them is a Hold. | Z3: No
A5: Decision | C5: =IF(OR(E11="No",E13="No",E14="No",E15="No"),"Hold",IF(COUNTA(E11:E20)<10,"",IF(AND(SUM(F11:F20)>=16,NOT(OR(E11="Partial",E13="Partial",E14="Partial",E15="Partial"))),"Ready","Fix first"))) | D5: =IF(C5="Hold","Don’t let this agent act for real users yet.",IF(C5="Fix first","No critical check is answered No, but the total is under 16 or a critical check is only Partial.",IF(C5="Ready","Every critical check is answered Yes, and the total is 16 or more.",IF(COUNTA(E11:E20)=0,"","Answer all 10 checks to see the decision."))))
A6: Total | C6: =SUM(F11:F20) | D6: out of 20. Yes scores 2, Partial 1, No 0. Ready needs 16 or more and every critical check answered Yes.
A7: Checks answered | C7: =COUNTA(E11:E20) | D7: out of 10
A8: Your next step | C8: =IF(MIN(Y11:Y20)<9,INDEX(B11:B20,MATCH(MIN(Y11:Y20),Y11:Y20,0)),IF(COUNTA(E11:E20)=10,"No open items.",""))
A10: # | B10: Check | E10: Answer | F10: Points | G10: Status | H10: Evidence from the other tabs
A11: 1 ★ | B11: Every action the agent can take is listed, including saving and restoring versions, sending, publishing and external calls. | F11: =IF(E11="Yes",2,IF(E11="Partial",1,IF(E11="No",0,""))) | G11: =IF(E11="Yes","Pass",IF(E11="Partial","Partial",IF(E11="No","Fail",""))) | H11: ="Actions listed (Tab 1): "&'1 · Action Inventory'!C28&" · "&"Actions with no authority (Tab 1): "&'1 · Action Inventory'!C35 | Y11: =IF(E11="No",1,IF(E11="Partial",3,9))
A12: 2 | B12: Each action’s undo was tested, not assumed. | F12: =IF(E12="Yes",2,IF(E12="Partial",1,IF(E12="No",0,""))) | G12: =IF(E12="Yes","Pass",IF(E12="Partial","Partial",IF(E12="No","Fail",""))) | H12: ="Undo not tested (Tab 1): "&'1 · Action Inventory'!C36 | Y12: =IF(E12="No",2,IF(E12="Partial",4,9))
A13: 3 ★ | B13: Every action that can’t be fully undone, or whose result others see, requires preview and consent. | F13: =IF(E13="Yes",2,IF(E13="Partial",1,IF(E13="No",0,""))) | G13: =IF(E13="Yes","Pass",IF(E13="Partial","Partial",IF(E13="No","Fail",""))) | H13: ="Consent removed by override (Tab 1): "&'1 · Action Inventory'!C39 | Y13: =IF(E13="No",1,IF(E13="Partial",3,9))
A14: 4 ★ | B14: Every preview shows the full change and says what can’t be undone. | F14: =IF(E14="Yes",2,IF(E14="Partial",1,IF(E14="No",0,""))) | G14: =IF(E14="Yes","Pass",IF(E14="Partial","Partial",IF(E14="No","Fail",""))) | H14: ="Previews that hide part of the change (Tab 2): "&'2 · Authority Requirements'!C35 | Y14: =IF(E14="No",1,IF(E14="Partial",3,9))
A15: 5 ★ | B15: Consent is given per change by a named person, not by a standing default. | F15: =IF(E15="Yes",2,IF(E15="Partial",1,IF(E15="No",0,""))) | G15: =IF(E15="Yes","Pass",IF(E15="Partial","Partial",IF(E15="No","Fail",""))) | H15: ="Consent that isn’t per change or has no named person (Tab 2): "&'2 · Authority Requirements'!C36 | Y15: =IF(E15="No",1,IF(E15="Partial",3,9))
A16: 6 | B16: The agent acts as the person who consented, and the log records who approved each change. | F16: =IF(E16="Yes",2,IF(E16="Partial",1,IF(E16="No",0,""))) | G16: =IF(E16="Yes","Pass",IF(E16="Partial","Partial",IF(E16="No","Fail",""))) | H16: ="Agent not acting as the consenting person (Tab 2): "&'2 · Authority Requirements'!C37 | Y16: =IF(E16="No",2,IF(E16="Partial",4,9))
A17: 7 | B17: If consent is refused, the agent changes nothing, or revises and asks again. | F17: =IF(E17="Yes",2,IF(E17="Partial",1,IF(E17="No",0,""))) | G17: =IF(E17="Yes","Pass",IF(E17="Partial","Partial",IF(E17="No","Fail",""))) | H17: ="No safe outcome on refusal (Tab 2): "&'2 · Authority Requirements'!C38 | Y17: =IF(E17="No",2,IF(E17="Partial",4,9))
A18: 8 | B18: Every override of the suggested authority has a written reason. | F18: =IF(E18="Yes",2,IF(E18="Partial",1,IF(E18="No",0,""))) | G18: =IF(E18="Yes","Pass",IF(E18="Partial","Partial",IF(E18="No","Fail",""))) | H18: ="Overrides with no reason (Tab 1): "&'1 · Action Inventory'!C38 | Y18: =IF(E18="No",2,IF(E18="Partial",4,9))
A19: 9 | B19: The agent’s access is no wider than the actions it needs; access for Not allowed actions has been removed. | F19: =IF(E19="Yes",2,IF(E19="Partial",1,IF(E19="No",0,""))) | G19: =IF(E19="Yes","Pass",IF(E19="Partial","Partial",IF(E19="No","Fail",""))) | H19: ="Not allowed, access still present (Tab 2): "&'2 · Authority Requirements'!C39 | Y19: =IF(E19="No",2,IF(E19="Partial",4,9))
A20: 10 | B20: A named owner re-runs this review whenever the agent gains a new action or tool. | F20: =IF(E20="Yes",2,IF(E20="Partial",1,IF(E20="No",0,""))) | G20: =IF(E20="Yes","Pass",IF(E20="Partial","Partial",IF(E20="No","Fail",""))) | Y20: =IF(E20="No",2,IF(E20="Partial",4,9))

Sheet Worked Example
A1: Illustrative example: an agent that drafts and edits a shared document for a user. Not a real system, company or real figures. | Z1: Yes
Z2: Partly
A3: 1 · Action Inventory | Z3: No
A4: What can the agent do, and can each action really be undone?
A5: Mark each action from a real undo attempt. Saving a version, restoring a version and renaming often feel reversible. Check what the history, notifications and other people’s screens show afterwards. | Z5: Nobody
Z6: The user only
A7: # | B7: Action | C7: What it changes | D7: Can it be undone? | E7: Who sees the result before it can be undone? | F7: Undo tested? | G7: Suggested authority | H7: Authority chosen | I7: Final authority | J7: Differs from suggestion? | K7: Reason for the difference | Z7: Other people
A8: 1 | B8: Draft text in the editor preview | C8: Text in the preview pane only | D8: Yes | E8: The user only | F8: Yes | G8: =IF(OR(B8="",D8="",E8=""),"",IF(AND(D8="Yes",OR(E8="Nobody",E8="The user only")),"Agent acts","Preview and consent")) | I8: =IF(H8<>"",H8,G8) | J8: =IF(AND(H8<>"",H8<>G8),"Yes","") | Z8: Another system
A9: 2 | B9: Apply an edit to the user’s working draft | C9: The user’s unsaved working draft | D9: Yes | E9: The user only | F9: Yes | G9: =IF(OR(B9="",D9="",E9=""),"",IF(AND(D9="Yes",OR(E9="Nobody",E9="The user only")),"Agent acts","Preview and consent")) | I9: =IF(H9<>"",H9,G9) | J9: =IF(AND(H9<>"",H9<>G9),"Yes","")
A10: 3 | B10: Save a new version | C10: Adds a version to the document’s history | D10: Partly | E10: Other people | F10: Yes | G10: =IF(OR(B10="",D10="",E10=""),"",IF(AND(D10="Yes",OR(E10="Nobody",E10="The user only")),"Agent acts","Preview and consent")) | I10: =IF(H10<>"",H10,G10) | J10: =IF(AND(H10<>"",H10<>G10),"Yes","") | Z10: Yes
A11: 4 | B11: Restore an earlier version | C11: Replaces the current text and adds a history entry | D11: Partly | E11: Other people | F11: No | G11: =IF(OR(B11="",D11="",E11=""),"",IF(AND(D11="Yes",OR(E11="Nobody",E11="The user only")),"Agent acts","Preview and consent")) | I11: =IF(H11<>"",H11,G11) | J11: =IF(AND(H11<>"",H11<>G11),"Yes","") | Z11: No
A12: 5 | B12: Publish to the shared space | C12: The copy everyone with access reads | D12: No | E12: Other people | F12: No | G12: =IF(OR(B12="",D12="",E12=""),"",IF(AND(D12="Yes",OR(E12="Nobody",E12="The user only")),"Agent acts","Preview and consent")) | I12: =IF(H12<>"",H12,G12) | J12: =IF(AND(H12<>"",H12<>G12),"Yes","")
A13: 6 | B13: Notify collaborators | C13: Sends a message to each collaborator | D13: No | E13: Other people | F13: No | G13: =IF(OR(B13="",D13="",E13=""),"",IF(AND(D13="Yes",OR(E13="Nobody",E13="The user only")),"Agent acts","Preview and consent")) | I13: =IF(H13<>"",H13,G13) | J13: =IF(AND(H13<>"",H13<>G13),"Yes","") | Z13: Agent acts
A14: 7 | B14: Delete a section | C14: Removes a section from the working draft | D14: Yes | E14: The user only | F14: No | G14: =IF(OR(B14="",D14="",E14=""),"",IF(AND(D14="Yes",OR(E14="Nobody",E14="The user only")),"Agent acts","Preview and consent")) | H14: Preview and consent | I14: =IF(H14<>"",H14,G14) | J14: =IF(AND(H14<>"",H14<>G14),"Yes","") | K14: Users don’t expect a section to disappear without being asked | Z14: Preview and consent
A15: 8 | B15: Rename the document | C15: The title everyone sees in the shared space | D15: Yes | E15: Other people | F15: Yes | G15: =IF(OR(B15="",D15="",E15=""),"",IF(AND(D15="Yes",OR(E15="Nobody",E15="The user only")),"Agent acts","Preview and consent")) | H15: Agent acts | I15: =IF(H15<>"",H15,G15) | J15: =IF(AND(H15<>"",H15<>G15),"Yes","") | Z15: Not allowed
A16: 9 | B16: Change sharing permissions | C16: Who can open and edit the document | D16: No | E16: Other people | F16: No | G16: =IF(OR(B16="",D16="",E16=""),"",IF(AND(D16="Yes",OR(E16="Nobody",E16="The user only")),"Agent acts","Preview and consent")) | H16: Not allowed | I16: =IF(H16<>"",H16,G16) | J16: =IF(AND(H16<>"",H16<>G16),"Yes","") | K16: The agent doesn’t need this; sharing stays with the user
A17: 10 | G17: =IF(OR(B17="",D17="",E17=""),"",IF(AND(D17="Yes",OR(E17="Nobody",E17="The user only")),"Agent acts","Preview and consent")) | I17: =IF(H17<>"",H17,G17) | J17: =IF(AND(H17<>"",H17<>G17),"Yes","") | Z17: Yes
A18: 11 | G18: =IF(OR(B18="",D18="",E18=""),"",IF(AND(D18="Yes",OR(E18="Nobody",E18="The user only")),"Agent acts","Preview and consent")) | I18: =IF(H18<>"",H18,G18) | J18: =IF(AND(H18<>"",H18<>G18),"Yes","") | Z18: Partial
A19: 12 | G19: =IF(OR(B19="",D19="",E19=""),"",IF(AND(D19="Yes",OR(E19="Nobody",E19="The user only")),"Agent acts","Preview and consent")) | I19: =IF(H19<>"",H19,G19) | J19: =IF(AND(H19<>"",H19<>G19),"Yes","") | Z19: No
A20: 13 | G20: =IF(OR(B20="",D20="",E20=""),"",IF(AND(D20="Yes",OR(E20="Nobody",E20="The user only")),"Agent acts","Preview and consent")) | I20: =IF(H20<>"",H20,G20) | J20: =IF(AND(H20<>"",H20<>G20),"Yes","")
A21: 14 | G21: =IF(OR(B21="",D21="",E21=""),"",IF(AND(D21="Yes",OR(E21="Nobody",E21="The user only")),"Agent acts","Preview and consent")) | I21: =IF(H21<>"",H21,G21) | J21: =IF(AND(H21<>"",H21<>G21),"Yes","") | Z21: Changes nothing
A22: 15 | G22: =IF(OR(B22="",D22="",E22=""),"",IF(AND(D22="Yes",OR(E22="Nobody",E22="The user only")),"Agent acts","Preview and consent")) | I22: =IF(H22<>"",H22,G22) | J22: =IF(AND(H22<>"",H22<>G22),"Yes","") | Z22: Revises and asks again
A23: 16 | G23: =IF(OR(B23="",D23="",E23=""),"",IF(AND(D23="Yes",OR(E23="Nobody",E23="The user only")),"Agent acts","Preview and consent")) | I23: =IF(H23<>"",H23,G23) | J23: =IF(AND(H23<>"",H23<>G23),"Yes","") | Z23: Proceeds anyway
A24: 17 | G24: =IF(OR(B24="",D24="",E24=""),"",IF(AND(D24="Yes",OR(E24="Nobody",E24="The user only")),"Agent acts","Preview and consent")) | I24: =IF(H24<>"",H24,G24) | J24: =IF(AND(H24<>"",H24<>G24),"Yes","") | Z24: Not decided
A25: 18 | G25: =IF(OR(B25="",D25="",E25=""),"",IF(AND(D25="Yes",OR(E25="Nobody",E25="The user only")),"Agent acts","Preview and consent")) | I25: =IF(H25<>"",H25,G25) | J25: =IF(AND(H25<>"",H25<>G25),"Yes","")
A26: 19 | G26: =IF(OR(B26="",D26="",E26=""),"",IF(AND(D26="Yes",OR(E26="Nobody",E26="The user only")),"Agent acts","Preview and consent")) | I26: =IF(H26<>"",H26,G26) | J26: =IF(AND(H26<>"",H26<>G26),"Yes","")
A27: 20 | G27: =IF(OR(B27="",D27="",E27=""),"",IF(AND(D27="Yes",OR(E27="Nobody",E27="The user only")),"Agent acts","Preview and consent")) | I27: =IF(H27<>"",H27,G27) | J27: =IF(AND(H27<>"",H27<>G27),"Yes","")
A29: Summary
A30: Actions listed | C30: =COUNTA(B8:B27)
A32: ACTIONS BY AUTHORITY | C32: Final | D32: Suggested
B33: Agent acts | C33: =COUNTIF(I8:I27,"Agent acts") | D33: =COUNTIF(G8:G27,"Agent acts")
B34: Preview and consent | C34: =COUNTIF(I8:I27,"Preview and consent") | D34: =COUNTIF(G8:G27,"Preview and consent")
B35: Not allowed | C35: =COUNTIF(I8:I27,"Not allowed") | D35: =COUNTIF(G8:G27,"Not allowed")
A37: Actions with no authority | C37: =SUMPRODUCT((B8:B27<>"")*(I8:I27="")) | D37: Actions with a name and no authority. Fill in D and E, or choose an authority.
A38: Undo not tested | C38: =SUMPRODUCT((B8:B27<>"")*(F8:F27<>"Yes")) | D38: Actions where nobody has actually tried the undo.
A39: Overrides | C39: =COUNTIF(J8:J27,"Yes") | D39: Actions where the authority chosen differs from the suggestion.
A40: Overrides with no reason | C40: =SUMPRODUCT((J8:J27="Yes")*(K8:K27="")) | D40: Write the reason in column K.
A41: Actions that need consent but the agent takes alone | C41: =COUNTIFS(G8:G27,"Preview and consent",I8:I27,"Agent acts") | D41: Suggested Preview and consent, chosen Agent acts: an override that removed consent.
A44: 2 · Authority Requirements
A45: Does each authority level have what it needs?
...
