Workbook

Sheet Start here
B4: Gate Routing Map
B5: A gate that only says pass or fail is hiding a decision. Give every case a route.
B7: WHAT TO BRING | C7: One agent you release through automated gates; the list of gate cases or eval suites it runs; for each one, what it checks and how bad it would be if it shipped broken; and the names of any systems that act on the agent’s output, with the teams that own their pipelines.
B9: WHAT TO DO | C9: List your gate cases, give each one a route (Block, Human decides, Check downstream or Track), fill in what each route needs, and score the ten checks.
B11: WHAT YOU LEAVE WITH | C11: A routing map for every gate case, a list of the cases whose route isn’t ready, and a decision: Ready, Fix first or Hold.
B13: THE FOUR ROUTES
B14: Route | C14: Use it when | D14: What the route needs before the release
B15: Block | C15: A regression case a check can decide on its own | D15: Enough trials, and every trial must pass (pass^k). One green run of a non-deterministic agent overstates its reliability.
B16: Human decides | C16: A serious case that no check can decide unambiguously | D16: A named owner, a backup owner, and halt criteria written down before the release. People watching releases get used to green and start reading small anomalies as noise.
B17: Check downstream | C17: Another system acts on the agent’s output and ships from its own pipeline | D17: The system and its owning team named; an output contract; the downstream side verifies that contract before either side deploys; a way to switch the new behaviour on together; a named person who can halt.
B18: Track | C18: Capability cases, or low-severity cases | D18: An owner who reviews the trend. A drop is worth investigating, not a reason to block.
B20: HOW TO USE IT | C20: Work left to right through tabs 1–3. The Worked Example tab shows a completed version.
B21: 1 · Gate Inventory | C21: Which route does each gate case need?
B22: 2 · Route Requirements | C22: Does each route have what it needs?
B23: 3 · Checklist | C23: Is the gate ready to decide releases?
B25: CELL LEGEND | C25: Shaded cells are yours to fill. Everything else calculates.
C26: Yours to fill | D26: Shaded, with a thin border.
C27: Calculates for you | D27: No fill, and locked.
C28: Does not apply | D28: On Tab 2, a column that is not for this row’s route.
B30: © The Living Craft · thelivingcraft.ai · Content CC BY 4.0
B31: Built by Sunil Mathew, co-authored with Claude
B33: THE LIVING CRAFT COHORT | C33: Build a working agentic system and develop the reasoning behind it. Explore The Living Craft’s October 2026 cohort: 30 live hours with Sunil Mathew, plus independent work.
C34: Apply at https://learning.thelivingcraft.ai/#apply

Sheet 1 · Gate Inventory
A1: 1 · Gate Inventory | Z1: Regression
A2: Which route does each gate case need? | Z2: Capability
A3: One row per gate case or eval suite. Columns D to G suggest a route. Leave “Route chosen” blank to accept the suggestion, or pick another and write down why.
Z4: Low
A5: # | B5: Case or suite | C5: What it checks | D5: Purpose | E5: Severity if it ships broken | F5: Who acts on the output | G5: Can a check decide it unambiguously? | H5: Deterministic? | I5: Suggested route | J5: Route chosen | K5: Final route | L5: Differs from suggestion? | M5: Reason for the difference | Z5: Medium
A6: 1 | I6: =IF(OR(B6="",D6="",E6="",F6="",G6=""),"",IF(D6="Capability","Track",IF(F6="Another system with its own pipeline","Check downstream",IF(E6="Low","Track",IF(G6="No","Human decides","Block"))))) | K6: =IF(J6<>"",J6,I6) | L6: =IF(AND(J6<>"",J6<>I6),"Yes","") | Z6: High
A7: 2 | I7: =IF(OR(B7="",D7="",E7="",F7="",G7=""),"",IF(D7="Capability","Track",IF(F7="Another system with its own pipeline","Check downstream",IF(E7="Low","Track",IF(G7="No","Human decides","Block"))))) | K7: =IF(J7<>"",J7,I7) | L7: =IF(AND(J7<>"",J7<>I7),"Yes","") | Z7: Critical
A8: 3 | I8: =IF(OR(B8="",D8="",E8="",F8="",G8=""),"",IF(D8="Capability","Track",IF(F8="Another system with its own pipeline","Check downstream",IF(E8="Low","Track",IF(G8="No","Human decides","Block"))))) | K8: =IF(J8<>"",J8,I8) | L8: =IF(AND(J8<>"",J8<>I8),"Yes","")
A9: 4 | I9: =IF(OR(B9="",D9="",E9="",F9="",G9=""),"",IF(D9="Capability","Track",IF(F9="Another system with its own pipeline","Check downstream",IF(E9="Low","Track",IF(G9="No","Human decides","Block"))))) | K9: =IF(J9<>"",J9,I9) | L9: =IF(AND(J9<>"",J9<>I9),"Yes","") | Z9: User directly
A10: 5 | I10: =IF(OR(B10="",D10="",E10="",F10="",G10=""),"",IF(D10="Capability","Track",IF(F10="Another system with its own pipeline","Check downstream",IF(E10="Low","Track",IF(G10="No","Human decides","Block"))))) | K10: =IF(J10<>"",J10,I10) | L10: =IF(AND(J10<>"",J10<>I10),"Yes","") | Z10: Another system in our pipeline
A11: 6 | I11: =IF(OR(B11="",D11="",E11="",F11="",G11=""),"",IF(D11="Capability","Track",IF(F11="Another system with its own pipeline","Check downstream",IF(E11="Low","Track",IF(G11="No","Human decides","Block"))))) | K11: =IF(J11<>"",J11,I11) | L11: =IF(AND(J11<>"",J11<>I11),"Yes","") | Z11: Another system with its own pipeline
A12: 7 | I12: =IF(OR(B12="",D12="",E12="",F12="",G12=""),"",IF(D12="Capability","Track",IF(F12="Another system with its own pipeline","Check downstream",IF(E12="Low","Track",IF(G12="No","Human decides","Block"))))) | K12: =IF(J12<>"",J12,I12) | L12: =IF(AND(J12<>"",J12<>I12),"Yes","")
A13: 8 | I13: =IF(OR(B13="",D13="",E13="",F13="",G13=""),"",IF(D13="Capability","Track",IF(F13="Another system with its own pipeline","Check downstream",IF(E13="Low","Track",IF(G13="No","Human decides","Block"))))) | K13: =IF(J13<>"",J13,I13) | L13: =IF(AND(J13<>"",J13<>I13),"Yes","") | Z13: Yes
A14: 9 | I14: =IF(OR(B14="",D14="",E14="",F14="",G14=""),"",IF(D14="Capability","Track",IF(F14="Another system with its own pipeline","Check downstream",IF(E14="Low","Track",IF(G14="No","Human decides","Block"))))) | K14: =IF(J14<>"",J14,I14) | L14: =IF(AND(J14<>"",J14<>I14),"Yes","") | Z14: No
A15: 10 | I15: =IF(OR(B15="",D15="",E15="",F15="",G15=""),"",IF(D15="Capability","Track",IF(F15="Another system with its own pipeline","Check downstream",IF(E15="Low","Track",IF(G15="No","Human decides","Block"))))) | K15: =IF(J15<>"",J15,I15) | L15: =IF(AND(J15<>"",J15<>I15),"Yes","")
A16: 11 | I16: =IF(OR(B16="",D16="",E16="",F16="",G16=""),"",IF(D16="Capability","Track",IF(F16="Another system with its own pipeline","Check downstream",IF(E16="Low","Track",IF(G16="No","Human decides","Block"))))) | K16: =IF(J16<>"",J16,I16) | L16: =IF(AND(J16<>"",J16<>I16),"Yes","") | Z16: Block
A17: 12 | I17: =IF(OR(B17="",D17="",E17="",F17="",G17=""),"",IF(D17="Capability","Track",IF(F17="Another system with its own pipeline","Check downstream",IF(E17="Low","Track",IF(G17="No","Human decides","Block"))))) | K17: =IF(J17<>"",J17,I17) | L17: =IF(AND(J17<>"",J17<>I17),"Yes","") | Z17: Human decides
A18: 13 | I18: =IF(OR(B18="",D18="",E18="",F18="",G18=""),"",IF(D18="Capability","Track",IF(F18="Another system with its own pipeline","Check downstream",IF(E18="Low","Track",IF(G18="No","Human decides","Block"))))) | K18: =IF(J18<>"",J18,I18) | L18: =IF(AND(J18<>"",J18<>I18),"Yes","") | Z18: Check downstream
A19: 14 | I19: =IF(OR(B19="",D19="",E19="",F19="",G19=""),"",IF(D19="Capability","Track",IF(F19="Another system with its own pipeline","Check downstream",IF(E19="Low","Track",IF(G19="No","Human decides","Block"))))) | K19: =IF(J19<>"",J19,I19) | L19: =IF(AND(J19<>"",J19<>I19),"Yes","") | Z19: Track
A20: 15 | I20: =IF(OR(B20="",D20="",E20="",F20="",G20=""),"",IF(D20="Capability","Track",IF(F20="Another system with its own pipeline","Check downstream",IF(E20="Low","Track",IF(G20="No","Human decides","Block"))))) | K20: =IF(J20<>"",J20,I20) | L20: =IF(AND(J20<>"",J20<>I20),"Yes","")
A21: 16 | I21: =IF(OR(B21="",D21="",E21="",F21="",G21=""),"",IF(D21="Capability","Track",IF(F21="Another system with its own pipeline","Check downstream",IF(E21="Low","Track",IF(G21="No","Human decides","Block"))))) | K21: =IF(J21<>"",J21,I21) | L21: =IF(AND(J21<>"",J21<>I21),"Yes","")
A22: 17 | I22: =IF(OR(B22="",D22="",E22="",F22="",G22=""),"",IF(D22="Capability","Track",IF(F22="Another system with its own pipeline","Check downstream",IF(E22="Low","Track",IF(G22="No","Human decides","Block"))))) | K22: =IF(J22<>"",J22,I22) | L22: =IF(AND(J22<>"",J22<>I22),"Yes","")
A23: 18 | I23: =IF(OR(B23="",D23="",E23="",F23="",G23=""),"",IF(D23="Capability","Track",IF(F23="Another system with its own pipeline","Check downstream",IF(E23="Low","Track",IF(G23="No","Human decides","Block"))))) | K23: =IF(J23<>"",J23,I23) | L23: =IF(AND(J23<>"",J23<>I23),"Yes","")
A24: 19 | I24: =IF(OR(B24="",D24="",E24="",F24="",G24=""),"",IF(D24="Capability","Track",IF(F24="Another system with its own pipeline","Check downstream",IF(E24="Low","Track",IF(G24="No","Human decides","Block"))))) | K24: =IF(J24<>"",J24,I24) | L24: =IF(AND(J24<>"",J24<>I24),"Yes","")
A25: 20 | I25: =IF(OR(B25="",D25="",E25="",F25="",G25=""),"",IF(D25="Capability","Track",IF(F25="Another system with its own pipeline","Check downstream",IF(E25="Low","Track",IF(G25="No","Human decides","Block"))))) | K25: =IF(J25<>"",J25,I25) | L25: =IF(AND(J25<>"",J25<>I25),"Yes","")
A27: Summary
A28: Cases listed | C28: =COUNTA(B6:B25)
A30: CASES BY ROUTE | C30: Final | D30: Suggested
B31: Block | C31: =COUNTIF(K6:K25,"Block") | D31: =COUNTIF(I6:I25,"Block")
B32: Human decides | C32: =COUNTIF(K6:K25,"Human decides") | D32: =COUNTIF(I6:I25,"Human decides")
B33: Check downstream | C33: =COUNTIF(K6:K25,"Check downstream") | D33: =COUNTIF(I6:I25,"Check downstream")
B34: Track | C34: =COUNTIF(K6:K25,"Track") | D34: =COUNTIF(I6:I25,"Track")
A36: Unrouted cases | C36: =SUMPRODUCT((B6:B25<>"")*(K6:K25="")) | D36: Cases with a name and no route. Fill in D to G, or pick a route.
A37: Overrides | C37: =COUNTIF(L6:L25,"Yes") | D37: Cases where the route chosen differs from the suggestion.
A38: Overrides with no reason | C38: =SUMPRODUCT((L6:L25="Yes")*(M6:M25="")) | D38: Write the reason in column M.

Sheet 2 · Route Requirements
A1: 2 · Route Requirements | Z1: Yes
A2: Does each route have what it needs? | Z2: No
A3: Rows mirror the Gate Inventory. Fill in only the columns for the row’s final route; the others are greyed out. Each row names the first thing missing.
Z4: Yes
A5: Minimum trials for non-deterministic Block cases | C5: 3 | D5: Agents vary between runs. A Block case on non-deterministic behaviour should pass every one of several trials. | Z5: Partial
Z6: No
E7: Block | G7: Human decides | J7: Check downstream | P7: Track
A8: # | B8: Case or suite | C8: Final route | D8: Deterministic? | E8: Trials per release | F8: Trials that must pass | G8: Owner | H8: Backup owner | I8: Halt criteria written before the release? | J8: Downstream system | K8: Team that owns its pipeline | L8: Output contract exists? | M8: Downstream verifies the contract before either side deploys? | N8: Both sides can switch the new behaviour on together? | O8: Who can halt the release | P8: Owner who reviews the trend | Q8: Route ready? | R8: Why not ready
A9: 1 | B9: =IF('1 · Gate Inventory'!B6="","",'1 · Gate Inventory'!B6) | C9: =IF('1 · Gate Inventory'!K6="","",'1 · Gate Inventory'!K6) | D9: =IF('1 · Gate Inventory'!H6="","",'1 · Gate Inventory'!H6) | Q9: =IF(C9="","",IF(R9="","Ready","Not ready")) | R9: =IF(C9="","",IF(C9="Block",IF(OR(E9="",E9<1),"No trials set",IF(F9="","Trials that must pass not set",IF(F9<E9,"Trials that must pass is lower than trials",IF(F9>E9,"Trials that must pass is more than trials",IF(AND(D9<>"Yes",E9<IF($C$5="",3,$C$5)),"Fewer trials than the minimum for non-deterministic cases",""))))),IF(C9="Human decides",IF(G9="","No owner",IF(I9<>"Yes","No halt criteria","")),IF(C9="Check downstream",IF(J9="","No downstream system named",IF(K9="","No team named for its pipeline",IF(L9="Partial","Output contract only partial",IF(L9<>"Yes","No output contract",IF(M9<>"Yes","Contract not verified before deploy",IF(N9<>"Yes","Cannot switch on together",IF(O9="","Nobody named who can halt",""))))))),IF(C9="Track",IF(P9="","No owner",""),"")))))
A10: 2 | B10: =IF('1 · Gate Inventory'!B7="","",'1 · Gate Inventory'!B7) | C10: =IF('1 · Gate Inventory'!K7="","",'1 · Gate Inventory'!K7) | D10: =IF('1 · Gate Inventory'!H7="","",'1 · Gate Inventory'!H7) | Q10: =IF(C10="","",IF(R10="","Ready","Not ready")) | R10: =IF(C10="","",IF(C10="Block",IF(OR(E10="",E10<1),"No trials set",IF(F10="","Trials that must pass not set",IF(F10<E10,"Trials that must pass is lower than trials",IF(F10>E10,"Trials that must pass is more than trials",IF(AND(D10<>"Yes",E10<IF($C$5="",3,$C$5)),"Fewer trials than the minimum for non-deterministic cases",""))))),IF(C10="Human decides",IF(G10="","No owner",IF(I10<>"Yes","No halt criteria","")),IF(C10="Check downstream",IF(J10="","No downstream system named",IF(K10="","No team named for its pipeline",IF(L10="Partial","Output contract only partial",IF(L10<>"Yes","No output contract",IF(M10<>"Yes","Contract not verified before deploy",IF(N10<>"Yes","Cannot switch on together",IF(O10="","Nobody named who can halt",""))))))),IF(C10="Track",IF(P10="","No owner",""),"")))))
A11: 3 | B11: =IF('1 · Gate Inventory'!B8="","",'1 · Gate Inventory'!B8) | C11: =IF('1 · Gate Inventory'!K8="","",'1 · Gate Inventory'!K8) | D11: =IF('1 · Gate Inventory'!H8="","",'1 · Gate Inventory'!H8) | Q11: =IF(C11="","",IF(R11="","Ready","Not ready")) | R11: =IF(C11="","",IF(C11="Block",IF(OR(E11="",E11<1),"No trials set",IF(F11="","Trials that must pass not set",IF(F11<E11,"Trials that must pass is lower than trials",IF(F11>E11,"Trials that must pass is more than trials",IF(AND(D11<>"Yes",E11<IF($C$5="",3,$C$5)),"Fewer trials than the minimum for non-deterministic cases",""))))),IF(C11="Human decides",IF(G11="","No owner",IF(I11<>"Yes","No halt criteria","")),IF(C11="Check downstream",IF(J11="","No downstream system named",IF(K11="","No team named for its pipeline",IF(L11="Partial","Output contract only partial",IF(L11<>"Yes","No output contract",IF(M11<>"Yes","Contract not verified before deploy",IF(N11<>"Yes","Cannot switch on together",IF(O11="","Nobody named who can halt",""))))))),IF(C11="Track",IF(P11="","No owner",""),"")))))
A12: 4 | B12: =IF('1 · Gate Inventory'!B9="","",'1 · Gate Inventory'!B9) | C12: =IF('1 · Gate Inventory'!K9="","",'1 · Gate Inventory'!K9) | D12: =IF('1 · Gate Inventory'!H9="","",'1 · Gate Inventory'!H9) | Q12: =IF(C12="","",IF(R12="","Ready","Not ready")) | R12: =IF(C12="","",IF(C12="Block",IF(OR(E12="",E12<1),"No trials set",IF(F12="","Trials that must pass not set",IF(F12<E12,"Trials that must pass is lower than trials",IF(F12>E12,"Trials that must pass is more than trials",IF(AND(D12<>"Yes",E12<IF($C$5="",3,$C$5)),"Fewer trials than the minimum for non-deterministic cases",""))))),IF(C12="Human decides",IF(G12="","No owner",IF(I12<>"Yes","No halt criteria","")),IF(C12="Check downstream",IF(J12="","No downstream system named",IF(K12="","No team named for its pipeline",IF(L12="Partial","Output contract only partial",IF(L12<>"Yes","No output contract",IF(M12<>"Yes","Contract not verified before deploy",IF(N12<>"Yes","Cannot switch on together",IF(O12="","Nobody named who can halt",""))))))),IF(C12="Track",IF(P12="","No owner",""),"")))))
A13: 5 | B13: =IF('1 · Gate Inventory'!B10="","",'1 · Gate Inventory'!B10) | C13: =IF('1 · Gate Inventory'!K10="","",'1 · Gate Inventory'!K10) | D13: =IF('1 · Gate Inventory'!H10="","",'1 · Gate Inventory'!H10) | Q13: =IF(C13="","",IF(R13="","Ready","Not ready")) | R13: =IF(C13="","",IF(C13="Block",IF(OR(E13="",E13<1),"No trials set",IF(F13="","Trials that must pass not set",IF(F13<E13,"Trials that must pass is lower than trials",IF(F13>E13,"Trials that must pass is more than trials",IF(AND(D13<>"Yes",E13<IF($C$5="",3,$C$5)),"Fewer trials than the minimum for non-deterministic cases",""))))),IF(C13="Human decides",IF(G13="","No owner",IF(I13<>"Yes","No halt criteria","")),IF(C13="Check downstream",IF(J13="","No downstream system named",IF(K13="","No team named for its pipeline",IF(L13="Partial","Output contract only partial",IF(L13<>"Yes","No output contract",IF(M13<>"Yes","Contract not verified before deploy",IF(N13<>"Yes","Cannot switch on together",IF(O13="","Nobody named who can halt",""))))))),IF(C13="Track",IF(P13="","No owner",""),"")))))
A14: 6 | B14: =IF('1 · Gate Inventory'!B11="","",'1 · Gate Inventory'!B11) | C14: =IF('1 · Gate Inventory'!K11="","",'1 · Gate Inventory'!K11) | D14: =IF('1 · Gate Inventory'!H11="","",'1 · Gate Inventory'!H11) | Q14: =IF(C14="","",IF(R14="","Ready","Not ready")) | R14: =IF(C14="","",IF(C14="Block",IF(OR(E14="",E14<1),"No trials set",IF(F14="","Trials that must pass not set",IF(F14<E14,"Trials that must pass is lower than trials",IF(F14>E14,"Trials that must pass is more than trials",IF(AND(D14<>"Yes",E14<IF($C$5="",3,$C$5)),"Fewer trials than the minimum for non-deterministic cases",""))))),IF(C14="Human decides",IF(G14="","No owner",IF(I14<>"Yes","No halt criteria","")),IF(C14="Check downstream",IF(J14="","No downstream system named",IF(K14="","No team named for its pipeline",IF(L14="Partial","Output contract only partial",IF(L14<>"Yes","No output contract",IF(M14<>"Yes","Contract not verified before deploy",IF(N14<>"Yes","Cannot switch on together",IF(O14="","Nobody named who can halt",""))))))),IF(C14="Track",IF(P14="","No owner",""),"")))))
A15: 7 | B15: =IF('1 · Gate Inventory'!B12="","",'1 · Gate Inventory'!B12) | C15: =IF('1 · Gate Inventory'!K12="","",'1 · Gate Inventory'!K12) | D15: =IF('1 · Gate Inventory'!H12="","",'1 · Gate Inventory'!H12) | Q15: =IF(C15="","",IF(R15="","Ready","Not ready")) | R15: =IF(C15="","",IF(C15="Block",IF(OR(E15="",E15<1),"No trials set",IF(F15="","Trials that must pass not set",IF(F15<E15,"Trials that must pass is lower than trials",IF(F15>E15,"Trials that must pass is more than trials",IF(AND(D15<>"Yes",E15<IF($C$5="",3,$C$5)),"Fewer trials than the minimum for non-deterministic cases",""))))),IF(C15="Human decides",IF(G15="","No owner",IF(I15<>"Yes","No halt criteria","")),IF(C15="Check downstream",IF(J15="","No downstream system named",IF(K15="","No team named for its pipeline",IF(L15="Partial","Output contract only partial",IF(L15<>"Yes","No output contract",IF(M15<>"Yes","Contract not verified before deploy",IF(N15<>"Yes","Cannot switch on together",IF(O15="","Nobody named who can halt",""))))))),IF(C15="Track",IF(P15="","No owner",""),"")))))
A16: 8 | B16: =IF('1 · Gate Inventory'!B13="","",'1 · Gate Inventory'!B13) | C16: =IF('1 · Gate Inventory'!K13="","",'1 · Gate Inventory'!K13) | D16: =IF('1 · Gate Inventory'!H13="","",'1 · Gate Inventory'!H13) | Q16: =IF(C16="","",IF(R16="","Ready","Not ready")) | R16: =IF(C16="","",IF(C16="Block",IF(OR(E16="",E16<1),"No trials set",IF(F16="","Trials that must pass not set",IF(F16<E16,"Trials that must pass is lower than trials",IF(F16>E16,"Trials that must pass is more than trials",IF(AND(D16<>"Yes",E16<IF($C$5="",3,$C$5)),"Fewer trials than the minimum for non-deterministic cases",""))))),IF(C16="Human decides",IF(G16="","No owner",IF(I16<>"Yes","No halt criteria","")),IF(C16="Check downstream",IF(J16="","No downstream system named",IF(K16="","No team named for its pipeline",IF(L16="Partial","Output contract only partial",IF(L16<>"Yes","No output contract",IF(M16<>"Yes","Contract not verified before deploy",IF(N16<>"Yes","Cannot switch on together",IF(O16="","Nobody named who can halt",""))))))),IF(C16="Track",IF(P16="","No owner",""),"")))))
A17: 9 | B17: =IF('1 · Gate Inventory'!B14="","",'1 · Gate Inventory'!B14) | C17: =IF('1 · Gate Inventory'!K14="","",'1 · Gate Inventory'!K14) | D17: =IF('1 · Gate Inventory'!H14="","",'1 · Gate Inventory'!H14) | Q17: =IF(C17="","",IF(R17="","Ready","Not ready")) | R17: =IF(C17="","",IF(C17="Block",IF(OR(E17="",E17<1),"No trials set",IF(F17="","Trials that must pass not set",IF(F17<E17,"Trials that must pass is lower than trials",IF(F17>E17,"Trials that must pass is more than trials",IF(AND(D17<>"Yes",E17<IF($C$5="",3,$C$5)),"Fewer trials than the minimum for non-deterministic cases",""))))),IF(C17="Human decides",IF(G17="","No owner",IF(I17<>"Yes","No halt criteria","")),IF(C17="Check downstream",IF(J17="","No downstream system named",IF(K17="","No team named for its pipeline",IF(L17="Partial","Output contract only partial",IF(L17<>"Yes","No output contract",IF(M17<>"Yes","Contract not verified before deploy",IF(N17<>"Yes","Cannot switch on together",IF(O17="","Nobody named who can halt",""))))))),IF(C17="Track",IF(P17="","No owner",""),"")))))
A18: 10 | B18: =IF('1 · Gate Inventory'!B15="","",'1 · Gate Inventory'!B15) | C18: =IF('1 · Gate Inventory'!K15="","",'1 · Gate Inventory'!K15) | D18: =IF('1 · Gate Inventory'!H15="","",'1 · Gate Inventory'!H15) | Q18: =IF(C18="","",IF(R18="","Ready","Not ready")) | R18: =IF(C18="","",IF(C18="Block",IF(OR(E18="",E18<1),"No trials set",IF(F18="","Trials that must pass not set",IF(F18<E18,"Trials that must pass is lower than trials",IF(F18>E18,"Trials that must pass is more than trials",IF(AND(D18<>"Yes",E18<IF($C$5="",3,$C$5)),"Fewer trials than the minimum for non-deterministic cases",""))))),IF(C18="Human decides",IF(G18="","No owner",IF(I18<>"Yes","No halt criteria","")),IF(C18="Check downstream",IF(J18="","No downstream system named",IF(K18="","No team named for its pipeline",IF(L18="Partial","Output contract only partial",IF(L18<>"Yes","No output contract",IF(M18<>"Yes","Contract not verified before deploy",IF(N18<>"Yes","Cannot switch on together",IF(O18="","Nobody named who can halt",""))))))),IF(C18="Track",IF(P18="","No owner",""),"")))))
A19: 11 | B19: =IF('1 · Gate Inventory'!B16="","",'1 · Gate Inventory'!B16) | C19: =IF('1 · Gate Inventory'!K16="","",'1 · Gate Inventory'!K16) | D19: =IF('1 · Gate Inventory'!H16="","",'1 · Gate Inventory'!H16) | Q19: =IF(C19="","",IF(R19="","Ready","Not ready")) | R19: =IF(C19="","",IF(C19="Block",IF(OR(E19="",E19<1),"No trials set",IF(F19="","Trials that must pass not set",IF(F19<E19,"Trials that must pass is lower than trials",IF(F19>E19,"Trials that must pass is more than trials",IF(AND(D19<>"Yes",E19<IF($C$5="",3,$C$5)),"Fewer trials than the minimum for non-deterministic cases",""))))),IF(C19="Human decides",IF(G19="","No owner",IF(I19<>"Yes","No halt criteria","")),IF(C19="Check downstream",IF(J19="","No downstream system named",IF(K19="","No team named for its pipeline",IF(L19="Partial","Output contract only partial",IF(L19<>"Yes","No output contract",IF(M19<>"Yes","Contract not verified before deploy",IF(N19<>"Yes","Cannot switch on together",IF(O19="","Nobody named who can halt",""))))))),IF(C19="Track",IF(P19="","No owner",""),"")))))
A20: 12 | B20: =IF('1 · Gate Inventory'!B17="","",'1 · Gate Inventory'!B17) | C20: =IF('1 · Gate Inventory'!K17="","",'1 · Gate Inventory'!K17) | D20: =IF('1 · Gate Inventory'!H17="","",'1 · Gate Inventory'!H17) | Q20: =IF(C20="","",IF(R20="","Ready","Not ready")) | R20: =IF(C20="","",IF(C20="Block",IF(OR(E20="",E20<1),"No trials set",IF(F20="","Trials that must pass not set",IF(F20<E20,"Trials that must pass is lower than trials",IF(F20>E20,"Trials that must pass is more than trials",IF(AND(D20<>"Yes",E20<IF($C$5="",3,$C$5)),"Fewer trials than the minimum for non-deterministic cases",""))))),IF(C20="Human decides",IF(G20="","No owner",IF(I20<>"Yes","No halt criteria","")),IF(C20="Check downstream",IF(J20="","No downstream system named",IF(K20="","No team named for its pipeline",IF(L20="Partial","Output contract only partial",IF(L20<>"Yes","No output contract",IF(M20<>"Yes","Contract not verified before deploy",IF(N20<>"Yes","Cannot switch on together",IF(O20="","Nobody named who can halt",""))))))),IF(C20="Track",IF(P20="","No owner",""),"")))))
... A28: 20 | B28: =IF('1 · Gate Inventory'!B25="","",'1 · Gate Inventory'!B25) | C28: =IF('1 · Gate Inventory'!K25="","",'1 · Gate Inventory'!K25) | D28: =IF('1 · Gate Inventory'!H25="","",'1 · Gate Inventory'!H25) | Q28: =IF(C28="","",IF(R28="","Ready","Not ready")) | R28: =IF(C28="","",IF(C28="Block",IF(OR(E28="",E28<1),"No trials set",IF(F28="","Trials that must pass not set",IF(F28<E28,"Trials that must pass is lower than trials",IF(F28>E28,"Trials that must pass is more than trials",IF(AND(D28<>"Yes",E28<IF($C$5="",3,$C$5)),"Fewer trials than the minimum for non-deterministic cases",""))))),IF(C28="Human decides",IF(G28="","No owner",IF(I28<>"Yes","No halt criteria","")),IF(C28="Check downstream",IF(J28="","No downstream system named",IF(K28="","No team named for its pipeline",IF(L28="Partial","Output contract only partial",IF(L28<>"Yes","No output contract",IF(M28<>"Yes","Contract not verified before deploy",IF(N28<>"Yes","Cannot switch on together",IF(O28="","Nobody named who can halt",""))))))),IF(C28="Track",IF(P28="","No owner",""),"")))))
A30: Summary
A31: BY ROUTE | C31: Cases | D31: Ready
B32: Block | C32: =COUNTIF(C9:C28,"Block") | D32: =COUNTIFS(C9:C28,"Block",Q9:Q28,"Ready")
B33: Human decides | C33: =COUNTIF(C9:C28,"Human decides") | D33: =COUNTIFS(C9:C28,"Human decides",Q9:Q28,"Ready")
B34: Check downstream | C34: =COUNTIF(C9:C28,"Check downstream") | D34: =COUNTIFS(C9:C28,"Check downstream",Q9:Q28,"Ready")
B35: Track | C35: =COUNTIF(C9:C28,"Track") | D35: =COUNTIFS(C9:C28,"Track",Q9:Q28,"Ready")
A37: Routes not ready | C37: =COUNTIF(Q9:Q28,"Not ready") | D37: Column R names the first thing missing on each.
A38: Block cases not ready | C38: =COUNTIFS(C9:C28,"Block",Q9:Q28,"Not ready")
A39: Human cases not ready | C39: =COUNTIFS(C9:C28,"Human decides",Q9:Q28,"Not ready")
A40: Human cases with no backup owner | C40: =SUMPRODUCT((C9:C28="Human decides")*(H9:H28="")) | D40: Scored by check 6, not by Route ready.
A41: Downstream cases without a verified contract | C41: =SUMPRODUCT((C9:C28="Check downstream")*(((L9:L28<>"Yes")+(M9:M28<>"Yes"))>0)) | D41: The contract is not Yes, or the downstream side does not verify it before deploying.

Sheet 3 · Checklist
A1: 3 · Checklist | Z1: Yes
A2: Is the gate ready to decide releases? | Z2: Partial
A3: Answer each check from evidence, not from memory. The four marked ★ are critical: a No on any one of them is a Hold. | Z3: No
A5: Decision | C5: =IF(OR(E11="No",E13="No",E15="No",E18="No"),"Hold",IF(COUNTA(E11:E20)<10,"",IF(AND(SUM(F11:F20)>=16,NOT(OR(E11="Partial",E13="Partial",E15="Partial",E18="Partial"))),"Ready","Fix first"))) | D5: =IF(C5="Hold","Don’t let this gate decide releases yet.",IF(C5="Fix first","No critical check is answered No, but the total is under 16 or a critical check is only Partial.",IF(C5="Ready","Every critical check is answered Yes, and the total is 16 or more.",IF(COUNTA(E11:E20)=0,"","Answer all 10 checks to see the decision."))))
A6: Total | C6: =SUM(F11:F20) | D6: out of 20. Yes scores 2, Partial 1, No 0. Ready needs 16 or more and every critical check answered Yes.
A7: Checks answered | C7: =COUNTA(E11:E20) | D7: out of 10
A8: Your next step | C8: =IF(MIN(Y11:Y20)<9,INDEX(B11:B20,MATCH(MIN(Y11:Y20),Y11:Y20,0)),IF(COUNTA(E11:E20)=10,"No open items.",""))
A10: # | B10: Check | E10: Answer | F10: Points | G10: Status | H10: Evidence from the other tabs
A11: 1 ★ | B11: Every gate case has a route. | F11: =IF(E11="Yes",2,IF(E11="Partial",1,IF(E11="No",0,""))) | G11: =IF(E11="Yes","Pass",IF(E11="Partial","Partial",IF(E11="No","Fail",""))) | H11: ="Unrouted cases (Tab 1): "&'1 · Gate Inventory'!C36 | Y11: =IF(E11="No",1,IF(E11="Partial",3,9))
A12: 2 | B12: Every route that differs from the suggestion has a written reason. | F12: =IF(E12="Yes",2,IF(E12="Partial",1,IF(E12="No",0,""))) | G12: =IF(E12="Yes","Pass",IF(E12="Partial","Partial",IF(E12="No","Fail",""))) | H12: ="Overrides with no reason (Tab 1): "&'1 · Gate Inventory'!C38 | Y12: =IF(E12="No",2,IF(E12="Partial",4,9))
A13: 3 ★ | B13: Block cases on non-deterministic behaviour run several trials and require every trial to pass. | F13: =IF(E13="Yes",2,IF(E13="Partial",1,IF(E13="No",0,""))) | G13: =IF(E13="Yes","Pass",IF(E13="Partial","Partial",IF(E13="No","Fail",""))) | H13: ="Block cases not ready (Tab 2): "&'2 · Route Requirements'!C38 | Y13: =IF(E13="No",1,IF(E13="Partial",3,9))
A14: 4 | B14: Capability cases are tracked, not used to block a release. | F14: =IF(E14="Yes",2,IF(E14="Partial",1,IF(E14="No",0,""))) | G14: =IF(E14="Yes","Pass",IF(E14="Partial","Partial",IF(E14="No","Fail",""))) | Y14: =IF(E14="No",2,IF(E14="Partial",4,9))
A15: 5 ★ | B15: Every Human decides case has a named owner and halt criteria written before the release. | F15: =IF(E15="Yes",2,IF(E15="Partial",1,IF(E15="No",0,""))) | G15: =IF(E15="Yes","Pass",IF(E15="Partial","Partial",IF(E15="No","Fail",""))) | H15: ="Human cases not ready (Tab 2): "&'2 · Route Requirements'!C39 | Y15: =IF(E15="No",1,IF(E15="Partial",3,9))
A16: 6 | B16: Every Human decides case has a backup owner, so a release never waits on one person. | F16: =IF(E16="Yes",2,IF(E16="Partial",1,IF(E16="No",0,""))) | G16: =IF(E16="Yes","Pass",IF(E16="Partial","Partial",IF(E16="No","Fail",""))) | H16: ="Human cases with no backup owner (Tab 2): "&'2 · Route Requirements'!C40 | Y16: =IF(E16="No",2,IF(E16="Partial",4,9))
A17: 7 | B17: Every Check downstream case names the system that acts on the output and the team that owns its pipeline. | F17: =IF(E17="Yes",2,IF(E17="Partial",1,IF(E17="No",0,""))) | G17: =IF(E17="Yes","Pass",IF(E17="Partial","Partial",IF(E17="No","Fail",""))) | Y17: =IF(E17="No",2,IF(E17="Partial",4,9))
A18: 8 ★ | B18: The agent’s output has a contract that the downstream system verifies before either side deploys. | F18: =IF(E18="Yes",2,IF(E18="Partial",1,IF(E18="No",0,""))) | G18: =IF(E18="Yes","Pass",IF(E18="Partial","Partial",IF(E18="No","Fail",""))) | H18: ="Downstream cases without a verified contract (Tab 2): "&'2 · Route Requirements'!C41 | Y18: =IF(E18="No",1,IF(E18="Partial",3,9))
A19: 9 | B19: New agent behaviour can be switched on together with the downstream system, and switched off without a redeploy. | F19: =IF(E19="Yes",2,IF(E19="Partial",1,IF(E19="No",0,""))) | G19: =IF(E19="Yes","Pass",IF(E19="Partial","Partial",IF(E19="No","Fail",""))) | Y19: =IF(E19="No",2,IF(E19="Partial",4,9))
A20: 10 | B20: Changes to the agent’s output are made in expand-then-contract steps, so the old and new shapes work side by side until the downstream system has moved. | F20: =IF(E20="Yes",2,IF(E20="Partial",1,IF(E20="No",0,""))) | G20: =IF(E20="Yes","Pass",IF(E20="Partial","Partial",IF(E20="No","Fail",""))) | Y20: =IF(E20="No",2,IF(E20="Partial",4,9))

Sheet Worked Example
A1: Illustrative example: an order-support agent whose refund recommendations are carried out by a separate payments service. Not a real system, company or real figures. | Z1: Regression
Z2: Capability
A3: 1 · Gate Inventory
A4: Which route does each gate case need? | Z4: Low
A5: One row per gate case or eval suite. Columns D to G suggest a route. Leave “Route chosen” blank to accept the suggestion, or pick another and write down why. | Z5: Medium
Z6: High
A7: # | B7: Case or suite | C7: What it checks | D7: Purpose | E7: Severity if it ships broken | F7: Who acts on the output | G7: Can a check decide it unambiguously? | H7: Deterministic? | I7: Suggested route | J7: Route chosen | K7: Final route | L7: Differs from suggestion? | M7: Reason for the difference | Z7: Critical
A8: 1 | B8: Refund amount within policy cap | C8: The recommended refund never exceeds the cap for the order type | D8: Regression | E8: Critical | F8: Another system with its own pipeline | G8: Yes | H8: Yes | I8: =IF(OR(B8="",D8="",E8="",F8="",G8=""),"",IF(D8="Capability","Track",IF(F8="Another system with its own pipeline","Check downstream",IF(E8="Low","Track",IF(G8="No","Human decides","Block"))))) | K8: =IF(J8<>"",J8,I8) | L8: =IF(AND(J8<>"",J8<>I8),"Yes","")
A9: 2 | B9: Refund recommendation matches the agreed format | C9: The recommendation parses against the format the payments service reads | D9: Regression | E9: High | F9: Another system with its own pipeline | G9: Yes | H9: Yes | I9: =IF(OR(B9="",D9="",E9="",F9="",G9=""),"",IF(D9="Capability","Track",IF(F9="Another system with its own pipeline","Check downstream",IF(E9="Low","Track",IF(G9="No","Human decides","Block"))))) | K9: =IF(J9<>"",J9,I9) | L9: =IF(AND(J9<>"",J9<>I9),"Yes","") | Z9: User directly
A10: 3 | B10: Picks the right order from the conversation | C10: The order the agent acts on is the one the customer meant | D10: Regression | E10: High | F10: User directly | G10: Yes | H10: No | I10: =IF(OR(B10="",D10="",E10="",F10="",G10=""),"",IF(D10="Capability","Track",IF(F10="Another system with its own pipeline","Check downstream",IF(E10="Low","Track",IF(G10="No","Human decides","Block"))))) | K10: =IF(J10<>"",J10,I10) | L10: =IF(AND(J10<>"",J10<>I10),"Yes","") | Z10: Another system in our pipeline
A11: 4 | B11: Declines refunds on accounts held for fraud review | C11: No refund is recommended while an account is on hold | D11: Regression | E11: Critical | F11: User directly | G11: No | H11: No | I11: =IF(OR(B11="",D11="",E11="",F11="",G11=""),"",IF(D11="Capability","Track",IF(F11="Another system with its own pipeline","Check downstream",IF(E11="Low","Track",IF(G11="No","Human decides","Block"))))) | K11: =IF(J11<>"",J11,I11) | L11: =IF(AND(J11<>"",J11<>I11),"Yes","") | Z11: Another system with its own pipeline
A12: 5 | B12: Tone of the customer reply | C12: The reply is polite and plain | D12: Regression | E12: Low | F12: User directly | G12: No | H12: No | I12: =IF(OR(B12="",D12="",E12="",F12="",G12=""),"",IF(D12="Capability","Track",IF(F12="Another system with its own pipeline","Check downstream",IF(E12="Low","Track",IF(G12="No","Human decides","Block"))))) | K12: =IF(J12<>"",J12,I12) | L12: =IF(AND(J12<>"",J12<>I12),"Yes","")
A13: 6 | B13: Resolves complaints that span several orders | C13: One reply settles a complaint about more than one order | D13: Capability | E13: High | F13: User directly | G13: Yes | H13: No | I13: =IF(OR(B13="",D13="",E13="",F13="",G13=""),"",IF(D13="Capability","Track",IF(F13="Another system with its own pipeline","Check downstream",IF(E13="Low","Track",IF(G13="No","Human decides","Block"))))) | K13: =IF(J13<>"",J13,I13) | L13: =IF(AND(J13<>"",J13<>I13),"Yes","") | Z13: Yes
A14: 7 | B14: Escalation note to the support team | C14: The note carries the order, the issue and what the agent already tried | D14: Regression | E14: Medium | F14: Another system in our pipeline | G14: Yes | H14: No | I14: =IF(OR(B14="",D14="",E14="",F14="",G14=""),"",IF(D14="Capability","Track",IF(F14="Another system with its own pipeline","Check downstream",IF(E14="Low","Track",IF(G14="No","Human decides","Block"))))) | K14: =IF(J14<>"",J14,I14) | L14: =IF(AND(J14<>"",J14<>I14),"Yes","") | Z14: No
A15: 8 | B15: Cites the correct policy clause | C15: The reply quotes the clause that applies to this order | D15: Regression | E15: High | F15: User directly | G15: No | H15: No | I15: =IF(OR(B15="",D15="",E15="",F15="",G15=""),"",IF(D15="Capability","Track",IF(F15="Another system with its own pipeline","Check downstream",IF(E15="Low","Track",IF(G15="No","Human decides","Block"))))) | J15: Block | K15: =IF(J15<>"",J15,I15) | L15: =IF(AND(J15<>"",J15<>I15),"Yes","") | M15: Graded by a model judge calibrated against human reviewers
A16: 9 | I16: =IF(OR(B16="",D16="",E16="",F16="",G16=""),"",IF(D16="Capability","Track",IF(F16="Another system with its own pipeline","Check downstream",IF(E16="Low","Track",IF(G16="No","Human decides","Block"))))) | K16: =IF(J16<>"",J16,I16) | L16: =IF(AND(J16<>"",J16<>I16),"Yes","") | Z16: Block
A17: 10 | I17: =IF(OR(B17="",D17="",E17="",F17="",G17=""),"",IF(D17="Capability","Track",IF(F17="Another system with its own pipeline","Check downstream",IF(E17="Low","Track",IF(G17="No","Human decides","Block"))))) | K17: =IF(J17<>"",J17,I17) | L17: =IF(AND(J17<>"",J17<>I17),"Yes","") | Z17: Human decides
A18: 11 | I18: =IF(OR(B18="",D18="",E18="",F18="",G18=""),"",IF(D18="Capability","Track",IF(F18="Another system with its own pipeline","Check downstream",IF(E18="Low","Track",IF(G18="No","Human decides","Block"))))) | K18: =IF(J18<>"",J18,I18) | L18: =IF(AND(J18<>"",J18<>I18),"Yes","") | Z18: Check downstream
A19: 12 | I19: =IF(OR(B19="",D19="",E19="",F19="",G19=""),"",IF(D19="Capability","Track",IF(F19="Another system with its own pipeline","Check downstream",IF(E19="Low","Track",IF(G19="No","Human decides","Block"))))) | K19: =IF(J19<>"",J19,I19) | L19: =IF(AND(J19<>"",J19<>I19),"Yes","") | Z19: Track
A20: 13 | I20: =IF(OR(B20="",D20="",E20="",F20="",G20=""),"",IF(D20="Capability","Track",IF(F20="Another system with its own pipeline","Check downstream",IF(E20="Low","Track",IF(G20="No","Human decides","Block"))))) | K20: =IF(J20<>"",J20,I20) | L20: =IF(AND(J20<>"",J20<>I20),"Yes","")
A21: 14 | I21: =IF(OR(B21="",D21="",E21="",F21="",G21=""),"",IF(D21="Capability","Track",IF(F21="Another system with its own pipeline","Check downstream",IF(E21="Low","Track",IF(G21="No","Human decides","Block"))))) | K21: =IF(J21<>"",J21,I21) | L21: =IF(AND(J21<>"",J21<>I21),"Yes","") | Z21: Yes
A22: 15 | I22: =IF(OR(B22="",D22="",E22="",F22="",G22=""),"",IF(D22="Capability","Track",IF(F22="Another system with its own pipeline","Check downstream",IF(E22="Low","Track",IF(G22="No","Human decides","Block"))))) | K22: =IF(J22<>"",J22,I22) | L22: =IF(AND(J22<>"",J22<>I22),"Yes","") | Z22: Partial
A23: 16 | I23: =IF(OR(B23="",D23="",E23="",F23="",G23=""),"",IF(D23="Capability","Track",IF(F23="Another system with its own pipeline","Check downstream",IF(E23="Low","Track",IF(G23="No","Human decides","Block"))))) | K23: =IF(J23<>"",J23,I23) | L23: =IF(AND(J23<>"",J23<>I23),"Yes","") | Z23: No
A24: 17 | I24: =IF(OR(B24="",D24="",E24="",F24="",G24=""),"",IF(D24="Capability","Track",IF(F24="Another system with its own pipeline","Check downstream",IF(E24="Low","Track",IF(G24="No","Human decides","Block"))))) | K24: =IF(J24<>"",J24,I24) | L24: =IF(AND(J24<>"",J24<>I24),"Yes","")
A25: 18 | I25: =IF(OR(B25="",D25="",E25="",F25="",G25=""),"",IF(D25="Capability","Track",IF(F25="Another system with its own pipeline","Check downstream",IF(E25="Low","Track",IF(G25="No","Human decides","Block"))))) | K25: =IF(J25<>"",J25,I25) | L25: =IF(AND(J25<>"",J25<>I25),"Yes","")
A26: 19 | I26: =IF(OR(B26="",D26="",E26="",F26="",G26=""),"",IF(D26="Capability","Track",IF(F26="Another system with its own pipeline","Check downstream",IF(E26="Low","Track",IF(G26="No","Human decides","Block"))))) | K26: =IF(J26<>"",J26,I26) | L26: =IF(AND(J26<>"",J26<>I26),"Yes","")
A27: 20 | I27: =IF(OR(B27="",D27="",E27="",F27="",G27=""),"",IF(D27="Capability","Track",IF(F27="Another system with its own pipeline","Check downstream",IF(E27="Low","Track",IF(G27="No","Human decides","Block"))))) | K27: =IF(J27<>"",J27,I27) | L27: =IF(AND(J27<>"",J27<>I27),"Yes","")
A29: Summary
A30: Cases listed | C30: =COUNTA(B8:B27)
A32: CASES BY ROUTE | C32: Final | D32: Suggested
B33: Block | C33: =COUNTIF(K8:K27,"Block") | D33: =COUNTIF(I8:I27,"Block")
B34: Human decides | C34: =COUNTIF(K8:K27,"Human decides") | D34: =COUNTIF(I8:I27,"Human decides")
B35: Check downstream | C35: =COUNTIF(K8:K27,"Check downstream") | D35: =COUNTIF(I8:I27,"Check downstream")
B36: Track | C36: =COUNTIF(K8:K27,"Track") | D36: =COUNTIF(I8:I27,"Track")
A38: Unrouted cases | C38: =SUMPRODUCT((B8:B27<>"")*(K8:K27="")) | D38: Cases with a name and no route. Fill in D to G, or pick a route.
A39: Overrides | C39: =COUNTIF(L8:L27,"Yes") | D39: Cases where the route chosen differs from the suggestion.
A40: Overrides with no reason | C40: =SUMPRODUCT((L8:L27="Yes")*(M8:M27="")) | D40: Write the reason in column M.
A43: 2 · Route Requirements
A44: Does each route have what it needs?
A45: Rows mirror the Gate Inventory. Fill in only the columns for the row’s final route; the others are greyed out. Each row names the first thing missing.
...
