Workbook

Sheet 0 · Start here
B4: RESOURCES · AGENTIC SYSTEM DESIGN
B6: Token Limit Framework
B7: Decide what your agent does when it's told no — before a traffic spike decides for you.
B8: Sunil Mathew · The Living Craft
B10: What to bring | C10: One agent workflow you run or plan to run, the steps it takes, rough token counts per step (from traces or an estimate), and the rate and token limits it runs under.
B12: What to do | C12: Map the steps, list every limit that can refuse the agent, model retry amplification at peak, define a stop state for every step with a side effect, and score the ten checks.
B14: What you leave with | C14: A token-limit policy for that workflow (per-task budget, retry rule, stop states with clean-up owners) and a decision: Ready to scale, Fix first, or Hold.
B16: How to use it | C16: Work left to right through tabs 1–5. The Worked Example tab shows a completed version.
B18: The five questions | C18: What does one run of this workflow cost, step by step? | D18: 1 · Workflow Map
C19: Which limits can refuse the agent, and who shares them? | D19: 2 · Limits
C20: How far can retries amplify spend at peak? | D20: 3 · Retry Amplifier
C21: If the agent stops at each step, what's left behind and who cleans it up? | D21: 4 · Stop States
C22: Is the limit policy good enough to scale? | D22: 5 · Decision
B24: Cell legend | C24: Shaded cells are yours to fill. Everything else calculates.
C25: Yours to fill | D25: Shaded, with a thin border.
C26: Calculates for you | D26: No fill, and locked.
B28: © The Living Craft · thelivingcraft.ai · Content CC BY 4.0

Sheet 1 · Workflow Map
A1: 1 · Workflow Map
A2: What does one run of this workflow cost, step by step?
A4: Step # | B4: Step name | C4: Calls a model? | D4: Calls an external API? | E4: Side effect | F4: Input tokens | G4: Output tokens | H4: Step tokens | I4: Cumulative tokens | J4: Idempotent on retry? | K4: Checkpoint saved after step?
B5: Plain words. "Read calendars", not "step 2". | E5: Holding a room is Reversible. Sending an invite is Irreversible. | F5: Tokens sent on this step, including carried context. | J5: Can this step safely run twice? | K5: Can a retry resume here instead of restarting?
A6: 1 | H6: =IF(AND(F6="",G6=""),"",SUM(F6:G6)) | I6: =IF(H6="","",SUM($H$6:H6)) | L6: =IF(K6="Yes",A6,0)
A7: 2 | H7: =IF(AND(F7="",G7=""),"",SUM(F7:G7)) | I7: =IF(H7="","",SUM($H$6:H7)) | L7: =IF(K7="Yes",A7,L6)
A8: 3 | H8: =IF(AND(F8="",G8=""),"",SUM(F8:G8)) | I8: =IF(H8="","",SUM($H$6:H8)) | L8: =IF(K8="Yes",A8,L7)
A9: 4 | H9: =IF(AND(F9="",G9=""),"",SUM(F9:G9)) | I9: =IF(H9="","",SUM($H$6:H9)) | L9: =IF(K9="Yes",A9,L8)
A10: 5 | H10: =IF(AND(F10="",G10=""),"",SUM(F10:G10)) | I10: =IF(H10="","",SUM($H$6:H10)) | L10: =IF(K10="Yes",A10,L9)
A11: 6 | H11: =IF(AND(F11="",G11=""),"",SUM(F11:G11)) | I11: =IF(H11="","",SUM($H$6:H11)) | L11: =IF(K11="Yes",A11,L10)
A12: 7 | H12: =IF(AND(F12="",G12=""),"",SUM(F12:G12)) | I12: =IF(H12="","",SUM($H$6:H12)) | L12: =IF(K12="Yes",A12,L11)
A13: 8 | H13: =IF(AND(F13="",G13=""),"",SUM(F13:G13)) | I13: =IF(H13="","",SUM($H$6:H13)) | L13: =IF(K13="Yes",A13,L12)
A14: 9 | H14: =IF(AND(F14="",G14=""),"",SUM(F14:G14)) | I14: =IF(H14="","",SUM($H$6:H14)) | L14: =IF(K14="Yes",A14,L13)
A15: 10 | H15: =IF(AND(F15="",G15=""),"",SUM(F15:G15)) | I15: =IF(H15="","",SUM($H$6:H15)) | L15: =IF(K15="Yes",A15,L14)
A16: 11 | H16: =IF(AND(F16="",G16=""),"",SUM(F16:G16)) | I16: =IF(H16="","",SUM($H$6:H16)) | L16: =IF(K16="Yes",A16,L15)
A17: 12 | H17: =IF(AND(F17="",G17=""),"",SUM(F17:G17)) | I17: =IF(H17="","",SUM($H$6:H17)) | L17: =IF(K17="Yes",A17,L16)
A19: Tokens per clean run | H19: =SUM(H6:H17)
A20: Steps with side effects | H20: =COUNTIF(E6:E17,"Reversible")+COUNTIF(E6:E17,"Irreversible")
A21: Unsafe steps (a side effect, and not idempotent) | H21: =COUNTIFS(E6:E17,"Reversible",J6:J17,"No")+COUNTIFS(E6:E17,"Irreversible",J6:J17,"No") | I21: Every one of these can be run twice by a retry.

Sheet 2 · Limits
A1: 2 · Limits
A2: Which limits can refuse the agent, and who shares them?
A4: # | B4: Limit | C4: Scope | D4: Value | E4: Unit | F4: Window | G4: Shared with | H4: Refusal signal | I4: Current handling | J4: Owner
G5: e.g. "all agents on this API key" | H5: e.g. "HTTP 429 + Retry-After"
A6: 1 | B6: model provider tokens per minute | K6: =IF(AND(E6="tokens",F6="per minute"),"tpm","")
A7: 2 | B7: model provider requests per minute | K7: =IF(AND(E7="tokens",F7="per minute"),"tpm","")
A8: 3 | B8: daily or monthly spend cap | K8: =IF(AND(E8="tokens",F8="per minute"),"tpm","")
A9: 4 | B9: max context window | K9: =IF(AND(E9="tokens",F9="per minute"),"tpm","")
A10: 5 | B10: downstream API rate limit (e.g. calendar) | K10: =IF(AND(E10="tokens",F10="per minute"),"tpm","")
A11: 6 | B11: your own per-task budget | K11: =IF(AND(E11="tokens",F11="per minute"),"tpm","")
A12: 7 | B12: per-user or per-tenant budget | K12: =IF(AND(E12="tokens",F12="per minute"),"tpm","")
A13: 8 | K13: =IF(AND(E13="tokens",F13="per minute"),"tpm","")
A14: 9 | K14: =IF(AND(E14="tokens",F14="per minute"),"tpm","")
A15: 10 | K15: =IF(AND(E15="tokens",F15="per minute"),"tpm","")
A17: Limits shared across workflows | D17: =COUNTIF(C6:C15,"Shared across workflows") | E17: One busy workflow can starve every other one on these.
A18: Limits retried immediately, or not handled at all | D18: =COUNTIF(I6:I15,"Retry immediately")+COUNTIF(I6:I15,"Unknown") | E18: An immediate retry is the pattern that amplifies a spike.

Sheet 3 · Retry Amplifier
A1: 3 · Retry Amplifier
A2: How far can retries amplify spend at peak?
A4: Inputs
A5: Tokens per clean run | D5: ='1 · Workflow Map'!H19 | E5: Linked from the workflow map. Type over it to model a different run. | N5: =AND(D5<>"",D6<>"",D7<>"",D8<>"")
A6: Step most likely to be refused (step #) | N6: =IF(N5,IF(D6<=1,0,INDEX('1 · Workflow Map'!I6:I17,D6-1)),"")
A7: Retry scope | E7: What a retry re-runs: the whole task, everything since the last checkpoint, or only the refused call. | N7: =IF(N5,IF(D6<=1,0,INDEX('1 · Workflow Map'!L6:L17,D6-1)),"")
A8: Max retries per task | N8: =IF(N5,IF(D6<=1,0,IF(N7=0,N6,N6-INDEX('1 · Workflow Map'!I6:I17,N7))),"")
A9: Refused calls count against quota? | D9: No | E9: Most providers don't bill rejected calls. Check yours.
A10: Peak tasks started per minute
A11: Token-per-minute limit for the shared quota | D11: =IFERROR(INDEX('2 · Limits'!D6:D15,MATCH("tpm",'2 · Limits'!K6:K15,0)),"") | E11: Linked from the first limit row with unit tokens and window per minute. Type over it if that is not the one.
A13: What retries cost
A14: Tokens repeated per failed attempt | D14: =IF(N5,IFERROR(IF(D7="Retry the call only",0,IF(D7="Restart task",N6,IF(D7="Resume from last checkpoint",N8,"")))+IF(D9="Yes",INDEX('1 · Workflow Map'!F6:F17,D6),0),""),"") | E14: Work already paid for that a retry pays for again.
A15: Worst case, eventually succeeds | D15: =IF(D14="","",D8*D14+D5)
A16: Worst case, gives up | D16: =IF(D14="","",(D8+1)*D14) | E16: Spent with nothing booked.
A17: Amplification factor | D17: =IF(D15="","",IFERROR(ROUND(D15/D5,2),"")) | E17: Worst case that succeeds, over one clean run.
A19: At peak
A20: Peak demand, normal | D20: =IF(OR(D10="",D5=""),"",D10*D5) | E20: Tokens per minute if nothing is refused.
A21: Peak demand, worst case | D21: =IF(OR(D10="",D15=""),"",D10*D15) | E21: Tokens per minute if every task is refused at that step.
A22: Quota used, normal | D22: =IF(OR(D20="",D11="",D11=0),"",IFERROR(D20/D11,"")) | E22: =IF(D22="","",IF(D22<=0.8,"Fits with headroom",IF(D22<=1,"Tight: any spike tips it over","Retries alone can exhaust the quota")))
A23: Quota used, worst case | D23: =IF(OR(D21="",D11="",D11=0),"",IFERROR(D21/D11,""))
A25: Verdict | D25: =IF(D23="","",IF(D23<=0.8,"Fits with headroom",IF(D23<=1,"Tight: any spike tips it over","Retries alone can exhaust the quota")))
A27: This is a planning bound, not a forecast. It assumes every task hits the limit at the same step. Real traffic is messier; use it to see whether your retry design can take the whole system down.

Sheet 4 · Stop States
A1: 4 · Stop States
A2: If the agent stops at each step, what's left behind and who cleans it up?
A4: Step # | B4: Step | C4: Side effect | D4: State left if the agent stops right after this step | E4: What the user sees | F4: Clean-up action | G4: Automatic or manual? | H4: Clean-up owner | I4: Can the task resume from here? | J4: Stop cost
D5: e.g. "Room held, no invites sent" | F5: e.g. "Release room hold after 15 min"
A6: 1 | B6: =IF('1 · Workflow Map'!B6="","",'1 · Workflow Map'!B6) | C6: =IF('1 · Workflow Map'!E6="","",'1 · Workflow Map'!E6) | O6: =IF(OR(C6="Reversible",C6="Irreversible"),IF(OR(F6="",H6=""),1,0),0)
A7: 2 | B7: =IF('1 · Workflow Map'!B7="","",'1 · Workflow Map'!B7) | C7: =IF('1 · Workflow Map'!E7="","",'1 · Workflow Map'!E7) | O7: =IF(OR(C7="Reversible",C7="Irreversible"),IF(OR(F7="",H7=""),1,0),0)
A8: 3 | B8: =IF('1 · Workflow Map'!B8="","",'1 · Workflow Map'!B8) | C8: =IF('1 · Workflow Map'!E8="","",'1 · Workflow Map'!E8) | O8: =IF(OR(C8="Reversible",C8="Irreversible"),IF(OR(F8="",H8=""),1,0),0)
A9: 4 | B9: =IF('1 · Workflow Map'!B9="","",'1 · Workflow Map'!B9) | C9: =IF('1 · Workflow Map'!E9="","",'1 · Workflow Map'!E9) | O9: =IF(OR(C9="Reversible",C9="Irreversible"),IF(OR(F9="",H9=""),1,0),0)
A10: 5 | B10: =IF('1 · Workflow Map'!B10="","",'1 · Workflow Map'!B10) | C10: =IF('1 · Workflow Map'!E10="","",'1 · Workflow Map'!E10) | O10: =IF(OR(C10="Reversible",C10="Irreversible"),IF(OR(F10="",H10=""),1,0),0)
A11: 6 | B11: =IF('1 · Workflow Map'!B11="","",'1 · Workflow Map'!B11) | C11: =IF('1 · Workflow Map'!E11="","",'1 · Workflow Map'!E11) | O11: =IF(OR(C11="Reversible",C11="Irreversible"),IF(OR(F11="",H11=""),1,0),0)
A12: 7 | B12: =IF('1 · Workflow Map'!B12="","",'1 · Workflow Map'!B12) | C12: =IF('1 · Workflow Map'!E12="","",'1 · Workflow Map'!E12) | O12: =IF(OR(C12="Reversible",C12="Irreversible"),IF(OR(F12="",H12=""),1,0),0)
A13: 8 | B13: =IF('1 · Workflow Map'!B13="","",'1 · Workflow Map'!B13) | C13: =IF('1 · Workflow Map'!E13="","",'1 · Workflow Map'!E13) | O13: =IF(OR(C13="Reversible",C13="Irreversible"),IF(OR(F13="",H13=""),1,0),0)
A14: 9 | B14: =IF('1 · Workflow Map'!B14="","",'1 · Workflow Map'!B14) | C14: =IF('1 · Workflow Map'!E14="","",'1 · Workflow Map'!E14) | O14: =IF(OR(C14="Reversible",C14="Irreversible"),IF(OR(F14="",H14=""),1,0),0)
A15: 10 | B15: =IF('1 · Workflow Map'!B15="","",'1 · Workflow Map'!B15) | C15: =IF('1 · Workflow Map'!E15="","",'1 · Workflow Map'!E15) | O15: =IF(OR(C15="Reversible",C15="Irreversible"),IF(OR(F15="",H15=""),1,0),0)
A16: 11 | B16: =IF('1 · Workflow Map'!B16="","",'1 · Workflow Map'!B16) | C16: =IF('1 · Workflow Map'!E16="","",'1 · Workflow Map'!E16) | O16: =IF(OR(C16="Reversible",C16="Irreversible"),IF(OR(F16="",H16=""),1,0),0)
A17: 12 | B17: =IF('1 · Workflow Map'!B17="","",'1 · Workflow Map'!B17) | C17: =IF('1 · Workflow Map'!E17="","",'1 · Workflow Map'!E17) | O17: =IF(OR(C17="Reversible",C17="Irreversible"),IF(OR(F17="",H17=""),1,0),0)
A19: Stop states with no clean-up plan | F19: =SUM(O6:O17) | G19: A step with a side effect, and no clean-up action or no owner.

Sheet 5 · Decision
A1: 5 · Decision
A2: Is the limit policy good enough to scale?
A4: # | B4: Check | C4: Answer | D4: Points | E4: From your own sheet
B5: ★ marks a critical check. One No on a critical check is a Hold, whatever the score. | D5: Yes 2 · Partial 1 · No 0
A6: 01 | B6: Every limit that can refuse the agent is listed, with its scope and owner. | D6: =IF(C6="","",IF(C6="Yes",2,IF(C6="Partial",1,IF(C6="No",0,"")))) | P6: 0 | Q6: =IF(AND(P6=1,C6="No"),1,0)
A7: 02 | B7: Retries back off with jitter and honour Retry-After. | D7: =IF(C7="","",IF(C7="Yes",2,IF(C7="Partial",1,IF(C7="No",0,"")))) | P7: 0 | Q7: =IF(AND(P7=1,C7="No"),1,0)
A8: ★ 03 | B8: Retries are capped per call and per task. | D8: =IF(C8="","",IF(C8="Yes",2,IF(C8="Partial",1,IF(C8="No",0,"")))) | P8: 1 | Q8: =IF(AND(P8=1,C8="No"),1,0)
A9: 04 | B9: Retries resume from a checkpoint instead of restarting the task. | D9: =IF(C9="","",IF(C9="Yes",2,IF(C9="Partial",1,IF(C9="No",0,"")))) | P9: 0 | Q9: =IF(AND(P9=1,C9="No"),1,0)
A10: ★ 05 | B10: The token budget belongs to the task, across all its attempts, not just to each call. | D10: =IF(C10="","",IF(C10="Yes",2,IF(C10="Partial",1,IF(C10="No",0,"")))) | P10: 1 | Q10: =IF(AND(P10=1,C10="No"),1,0)
A11: 06 | B11: A shared quota is partitioned or prioritised, so one busy workflow can't starve the others. | D11: =IF(C11="","",IF(C11="Yes",2,IF(C11="Partial",1,IF(C11="No",0,"")))) | P11: 0 | Q11: =IF(AND(P11=1,C11="No"),1,0)
A12: 07 | B12: New work stops (circuit breaker) when the refusal rate crosses a set threshold. | D12: =IF(C12="","",IF(C12="Yes",2,IF(C12="Partial",1,IF(C12="No",0,"")))) | P12: 0 | Q12: =IF(AND(P12=1,C12="No"),1,0)
A13: ★ 08 | B13: Every step with a side effect has a defined stop state, a clean-up action and an owner. | D13: =IF(C13="","",IF(C13="Yes",2,IF(C13="Partial",1,IF(C13="No",0,"")))) | E13: ="Stop states with no clean-up plan: "&'4 · Stop States'!F19 | P13: 1 | Q13: =IF(AND(P13=1,C13="No"),1,0)
A14: ★ 09 | B14: Worst-case peak demand, with retries, fits within the quota. | D14: =IF(C14="","",IF(C14="Yes",2,IF(C14="Partial",1,IF(C14="No",0,"")))) | E14: ='3 · Retry Amplifier'!D25 | P14: 1 | Q14: =IF(AND(P14=1,C14="No"),1,0)
A15: 10 | B15: Budget exhaustion raises an alert that a named person owns. | D15: =IF(C15="","",IF(C15="Yes",2,IF(C15="Partial",1,IF(C15="No",0,"")))) | P15: 0 | Q15: =IF(AND(P15=1,C15="No"),1,0)
A17: Total | D17: =SUM(D6:D15) | E17: Out of 20. | P17: =COUNTIF(C6:C15,"Yes")+COUNTIF(C6:C15,"Partial")+COUNTIF(C6:C15,"No")
A18: Critical checks answered No | D18: =SUM(Q6:Q15)
A20: Decision | C20: =IF(P17<10,"Not scored yet",IF(D18>0,"Hold",IF(D17>=16,"Ready to scale","Fix first")))
C21: =IF(C20="Hold","Don't scale this workflow yet.",IF(C20="Fix first","Fix the checks answered No or Partial, then score it again.",IF(C20="Ready to scale","The limit policy holds at peak. Scale it.",IF(C20="Not scored yet","Answer all ten checks to get a decision.",""))))
A23: Your limit policy
A24: The one-page artefact. Fill this in and take it to your team.
A25: Per-task token budget | E25: Across every attempt, not per call.
A26: Max retries | E26: Per call and per task.
A27: Backoff | E27: Base delay, max delay, jitter Yes/No.
A28: Circuit-breaker threshold | E28: The refusal rate at which new work stops.
A29: Shed first under pressure | E29: Which work is refused first.
A30: Degrade option | E30: Smaller model, shorter context, or queue for later.

Sheet 6 · Worked Example
A1: Illustrative example. Not a real system or real figures.
A2: A scheduling agent. Six steps, two of them with side effects, run at peak against a token-per-minute quota shared with every other workflow on the same key.
A4: 1 · Workflow Map
A5: What does one run of this workflow cost, step by step?
A7: Step # | B7: Step name | C7: Calls a model? | D7: Calls an external API? | E7: Side effect | F7: Input tokens | G7: Output tokens | H7: Step tokens | I7: Cumulative tokens | J7: Idempotent on retry? | K7: Checkpoint saved after step?
B8: Plain words. "Read calendars", not "step 2". | E8: Holding a room is Reversible. Sending an invite is Irreversible. | F8: Tokens sent on this step, including carried context. | J8: Can this step safely run twice? | K8: Can a retry resume here instead of restarting?
A9: 1 | B9: Parse request | C9: Yes | D9: No | E9: None | F9: 1500 | G9: 300 | H9: =IF(AND(F9="",G9=""),"",SUM(F9:G9)) | I9: =IF(H9="","",SUM($H$9:H9)) | J9: Yes | K9: No | N9: =IF(K9="Yes",A9,0)
A10: 2 | B10: Read calendars | C10: Yes | D10: Yes | E10: None | F10: 6000 | G10: 800 | H10: =IF(AND(F10="",G10=""),"",SUM(F10:G10)) | I10: =IF(H10="","",SUM($H$9:H10)) | J10: Yes | K10: No | N10: =IF(K10="Yes",A10,N9)
A11: 3 | B11: Propose slots | C11: Yes | D11: No | E11: None | F11: 7500 | G11: 600 | H11: =IF(AND(F11="",G11=""),"",SUM(F11:G11)) | I11: =IF(H11="","",SUM($H$9:H11)) | J11: Yes | K11: No | N11: =IF(K11="Yes",A11,N10)
A12: 4 | B12: Hold room | C12: Yes | D12: Yes | E12: Reversible | F12: 8200 | G12: 200 | H12: =IF(AND(F12="",G12=""),"",SUM(F12:G12)) | I12: =IF(H12="","",SUM($H$9:H12)) | J12: No | K12: No | N12: =IF(K12="Yes",A12,N11)
A13: 5 | B13: Send invites | C13: Yes | D13: Yes | E13: Irreversible | F13: 8500 | G13: 400 | H13: =IF(AND(F13="",G13=""),"",SUM(F13:G13)) | I13: =IF(H13="","",SUM($H$9:H13)) | J13: No | K13: No | N13: =IF(K13="Yes",A13,N12)
A14: 6 | B14: Confirm to user | C14: Yes | D14: No | E14: None | F14: 9000 | G14: 300 | H14: =IF(AND(F14="",G14=""),"",SUM(F14:G14)) | I14: =IF(H14="","",SUM($H$9:H14)) | J14: Yes | K14: No | N14: =IF(K14="Yes",A14,N13)
A16: Tokens per clean run | H16: =SUM(H9:H14)
A17: Steps with side effects | H17: =COUNTIF(E9:E14,"Reversible")+COUNTIF(E9:E14,"Irreversible")
A18: Unsafe steps (a side effect, and not idempotent) | H18: =COUNTIFS(E9:E14,"Reversible",J9:J14,"No")+COUNTIFS(E9:E14,"Irreversible",J9:J14,"No") | I18: Every one of these can be run twice by a retry.
A21: 2 · Limits
A22: Which limits can refuse the agent, and who shares them?
A24: # | B24: Limit | C24: Scope | D24: Value | E24: Unit | F24: Window | G24: Shared with | H24: Refusal signal | I24: Current handling | J24: Owner
G25: e.g. "all agents on this API key" | H25: e.g. "HTTP 429 + Retry-After"
A26: 1 | B26: Model provider tokens per minute | C26: Shared across workflows | D26: 10000000 | E26: tokens | F26: per minute | G26: all agents on this API key | H26: HTTP 429 + Retry-After | I26: Retry with backoff | J26: Platform team | O26: =IF(AND(E26="tokens",F26="per minute"),"tpm","")
A27: 2 | B27: Model provider requests per minute | C27: Shared across workflows | D27: 4000 | E27: requests | F27: per minute | G27: all agents on this API key | H27: HTTP 429 + Retry-After | I27: Retry with backoff | J27: Platform team | O27: =IF(AND(E27="tokens",F27="per minute"),"tpm","")
A28: 3 | B28: Calendar API writes | C28: Per tenant | D28: 600 | E28: requests | F28: per minute | G28: scheduling agent only | H28: HTTP 429, no Retry-After | I28: Queue | J28: Workplace IT | O28: =IF(AND(E28="tokens",F28="per minute"),"tpm","")
A29: 4 | B29: Per-task token budget | C29: Per task | D29: 120000 | E29: tokens | F29: per request | G29: not shared | H29: budget guard refuses the call | I29: Fail task | J29: Scheduling team | O29: =IF(AND(E29="tokens",F29="per minute"),"tpm","")
A30: 5 | O30: =IF(AND(E30="tokens",F30="per minute"),"tpm","")
A31: 6 | O31: =IF(AND(E31="tokens",F31="per minute"),"tpm","")
A32: 7 | O32: =IF(AND(E32="tokens",F32="per minute"),"tpm","")
A33: 8 | O33: =IF(AND(E33="tokens",F33="per minute"),"tpm","")
A34: 9 | O34: =IF(AND(E34="tokens",F34="per minute"),"tpm","")
A35: 10 | O35: =IF(AND(E35="tokens",F35="per minute"),"tpm","")
A37: Limits shared across workflows | D37: =COUNTIF(C26:C35,"Shared across workflows") | E37: One busy workflow can starve every other one on these.
A38: Limits retried immediately, or not handled at all | D38: =COUNTIF(I26:I35,"Retry immediately")+COUNTIF(I26:I35,"Unknown") | E38: An immediate retry is the pattern that amplifies a spike.
A41: 3 · Retry Amplifier
A42: How far can retries amplify spend at peak?
A44: Inputs
A45: Tokens per clean run | D45: =H16 | E45: Linked from the workflow map. Type over it to model a different run. | P45: =AND(D45<>"",D46<>"",D47<>"",D48<>"")
A46: Step most likely to be refused (step #) | D46: 4 | P46: =IF(P45,IF(D46<=1,0,INDEX(I9:I14,D46-1)),"")
A47: Retry scope | D47: Restart task | E47: What a retry re-runs: the whole task, everything since the last checkpoint, or only the refused call. | P47: =IF(P45,IF(D46<=1,0,INDEX(N9:N14,D46-1)),"")
A48: Max retries per task | D48: 3 | P48: =IF(P45,IF(D46<=1,0,IF(P47=0,P46,P46-INDEX(I9:I14,P47))),"")
A49: Refused calls count against quota? | D49: No | E49: Most providers don't bill rejected calls. Check yours.
A50: Peak tasks started per minute | D50: 200
...
